Workbook

Sheet Summary
A1: ملخص الفوارق بين ملف المحطات وملف OMC Staff Per Shift
A3: البند | B3: Line 1 | C3: Line 2 | D3: Line 3 | E3: Line 4 | F3: Line 5 | G3: Line 6 | H3: المجموع
A4: نوع المحطة | B4: =COUNTIFS(Comparison!$B$3:$B$94,"Line 1",Comparison!$H$3:$H$94,"✗") -> 0 | C4: =COUNTIFS(Comparison!$B$3:$B$94,"Line 2",Comparison!$H$3:$H$94,"✗") -> 0 | D4: =COUNTIFS(Comparison!$B$3:$B$94,"Line 3",Comparison!$H$3:$H$94,"✗") -> 1 | E4: =COUNTIFS(Comparison!$B$3:$B$94,"Line 4",Comparison!$H$3:$H$94,"✗") -> 4 | F4: =COUNTIFS(Comparison!$B$3:$B$94,"Line 5",Comparison!$H$3:$H$94,"✗") -> 1 | G4: =COUNTIFS(Comparison!$B$3:$B$94,"Line 6",Comparison!$H$3:$H$94,"✗") -> 1 | H4: =SUM(B4:G4) -> 7
A5: تشغيل 24 ساعة | B5: =COUNTIFS(Comparison!$B$3:$B$94,"Line 1",Comparison!$K$3:$K$94,"✗") -> 0 | C5: =COUNTIFS(Comparison!$B$3:$B$94,"Line 2",Comparison!$K$3:$K$94,"✗") -> 0 | D5: =COUNTIFS(Comparison!$B$3:$B$94,"Line 3",Comparison!$K$3:$K$94,"✗") -> 0 | E5: =COUNTIFS(Comparison!$B$3:$B$94,"Line 4",Comparison!$K$3:$K$94,"✗") -> 0 | F5: =COUNTIFS(Comparison!$B$3:$B$94,"Line 5",Comparison!$K$3:$K$94,"✗") -> 0 | G5: =COUNTIFS(Comparison!$B$3:$B$94,"Line 6",Comparison!$K$3:$K$94,"✗") -> 0 | H5: =SUM(B5:G5) -> 0
A6: عدد الأرصفة | B6: =COUNTIFS(Comparison!$B$3:$B$94,"Line 1",Comparison!$N$3:$N$94,"✗") -> 0 | C6: =COUNTIFS(Comparison!$B$3:$B$94,"Line 2",Comparison!$N$3:$N$94,"✗") -> 0 | D6: =COUNTIFS(Comparison!$B$3:$B$94,"Line 3",Comparison!$N$3:$N$94,"✗") -> 2 | E6: =COUNTIFS(Comparison!$B$3:$B$94,"Line 4",Comparison!$N$3:$N$94,"✗") -> 1 | F6: =COUNTIFS(Comparison!$B$3:$B$94,"Line 5",Comparison!$N$3:$N$94,"✗") -> 0 | G6: =COUNTIFS(Comparison!$B$3:$B$94,"Line 6",Comparison!$N$3:$N$94,"✗") -> 1 | H6: =SUM(B6:G6) -> 4
A7: مكاتب التذاكر | B7: =COUNTIFS(Comparison!$B$3:$B$94,"Line 1",Comparison!$Q$3:$Q$94,"✗") -> 0 | C7: =COUNTIFS(Comparison!$B$3:$B$94,"Line 2",Comparison!$Q$3:$Q$94,"✗") -> 0 | D7: =COUNTIFS(Comparison!$B$3:$B$94,"Line 3",Comparison!$Q$3:$Q$94,"✗") -> 2 | E7: =COUNTIFS(Comparison!$B$3:$B$94,"Line 4",Comparison!$Q$3:$Q$94,"✗") -> 0 | F7: =COUNTIFS(Comparison!$B$3:$B$94,"Line 5",Comparison!$Q$3:$Q$94,"✗") -> 0 | G7: =COUNTIFS(Comparison!$B$3:$B$94,"Line 6",Comparison!$Q$3:$Q$94,"✗") -> 0 | H7: =SUM(B7:G7) -> 2
A8: إجمالي بوابات AFC | B8: =COUNTIFS(Comparison!$B$3:$B$94,"Line 1",Comparison!$T$3:$T$94,"✗") -> 0 | C8: =COUNTIFS(Comparison!$B$3:$B$94,"Line 2",Comparison!$T$3:$T$94,"✗") -> 0 | D8: =COUNTIFS(Comparison!$B$3:$B$94,"Line 3",Comparison!$T$3:$T$94,"✗") -> 2 | E8: =COUNTIFS(Comparison!$B$3:$B$94,"Line 4",Comparison!$T$3:$T$94,"✗") -> 0 | F8: =COUNTIFS(Comparison!$B$3:$B$94,"Line 5",Comparison!$T$3:$T$94,"✗") -> 4 | G8: =COUNTIFS(Comparison!$B$3:$B$94,"Line 6",Comparison!$T$3:$T$94,"✗") -> 0 | H8: =SUM(B8:G8) -> 6
A9: بنوك AFC / Ticket Barriers | B9: =COUNTIFS(Comparison!$B$3:$B$94,"Line 1",Comparison!$W$3:$W$94,"✗") -> 0 | C9: =COUNTIFS(Comparison!$B$3:$B$94,"Line 2",Comparison!$W$3:$W$94,"✗") -> 0 | D9: =COUNTIFS(Comparison!$B$3:$B$94,"Line 3",Comparison!$W$3:$W$94,"✗") -> 20 | E9: =COUNTIFS(Comparison!$B$3:$B$94,"Line 4",Comparison!$W$3:$W$94,"✗") -> 4 | F9: =COUNTIFS(Comparison!$B$3:$B$94,"Line 5",Comparison!$W$3:$W$94,"✗") -> 11 | G9: =COUNTIFS(Comparison!$B$3:$B$94,"Line 6",Comparison!$W$3:$W$94,"✗") -> 6 | H9: =SUM(B9:G9) -> 41
A10: فرق في عدد حراس الأمن (OMC ≠ وردية E) | B10: =SUMPRODUCT((Comparison!$B$3:$B$94="Line 1")*ISNUMBER(Comparison!$AC$3:$AC$94)*(Comparison!$AC$3:$AC$94<>0)) -> 12 | C10: =SUMPRODUCT((Comparison!$B$3:$B$94="Line 2")*ISNUMBER(Comparison!$AC$3:$AC$94)*(Comparison!$AC$3:$AC$94<>0)) -> 14 | D10: =SUMPRODUCT((Comparison!$B$3:$B$94="Line 3")*ISNUMBER(Comparison!$AC$3:$AC$94)*(Comparison!$AC$3:$AC$94<>0)) -> 5 | E10: =SUMPRODUCT((Comparison!$B$3:$B$94="Line 4")*ISNUMBER(Comparison!$AC$3:$AC$94)*(Comparison!$AC$3:$AC$94<>0)) -> 5 | F10: =SUMPRODUCT((Comparison!$B$3:$B$94="Line 5")*ISNUMBER(Comparison!$AC$3:$AC$94)*(Comparison!$AC$3:$AC$94<>0)) -> 1 | G10: =SUMPRODUCT((Comparison!$B$3:$B$94="Line 6")*ISNUMBER(Comparison!$AC$3:$AC$94)*(Comparison!$AC$3:$AC$94<>0)) -> 1 | H10: =SUM(B10:G10) -> 38
A11: عدد المحطات | B11: =COUNTIF(Comparison!$B$3:$B$94,"Line 1") -> 25 | C11: =COUNTIF(Comparison!$B$3:$B$94,"Line 2") -> 15 | D11: =COUNTIF(Comparison!$B$3:$B$94,"Line 3") -> 22 | E11: =COUNTIF(Comparison!$B$3:$B$94,"Line 4") -> 9 | F11: =COUNTIF(Comparison!$B$3:$B$94,"Line 5") -> 12 | G11: =COUNTIF(Comparison!$B$3:$B$94,"Line 6") -> 9 | H11: =SUM(B11:G11) -> 92
A13: ملاحظات:
A14: • الأرقام أعلاه معادلات تُحسب تلقائياً من شيت Comparison (عدد الخانات المختلفة).
A15: • الخانات الحمراء في شيت Comparison = اختلاف بين الملفين.
A16: • بنوك AFC في الخطوط 3-6: ملف المحطات دائماً ضعف ملف OMC (عمود OMC اسمه Ticket Barriers) – يحتاج توحيد طريقة العد.
A17: • الأمن: ملف OMC = الحد الأدنى لكل وردية (مجموع بنود العقد)، وملف المحطات = حراس لكل وردية؛ المقارنة مع وردية E تقريبية.
A18: • تم استبعاد صفّي 4B1 و4C1 المكررين في قسم Line 6 بشيت FLOW (أرقامهم أصفار) – انظر شيت Data Issues.
A19: • المستودعات (Depots) موجودة في ملف المحطات فقط ولم تُدرج في المقارنة.

Sheet Comparison
A1: Station | F1: Type | I1: 24H | L1: Platforms | O1: Ticket Offices | R1: AFC Total | U1: AFC Bank / Ticket Barriers | X1: Security Guards
A2: Code | B2: Line | C2: Name – Stations file | D2: Name – OMC file | E2: OMC sheet | F2: Stations file | G2: OMC file | H2: Match | I2: Stations file | J2: OMC file | K2: Match | L2: Stations file | M2: OMC file | N2: Match | O2: Stations file | P2: OMC file | Q2: Match | R2: Stations file | S2: OMC file | T2: Match | U2: Stations file | V2: OMC file | W2: Match | X2: SecG E-shift | Y2: SecG L-shift | Z2: SecG N-shift | AA2: SecG Total/day | AB2: OMC SecG per shift (incl. P&R) | AC2: Diff (OMC − E-shift) | AD2: Total mismatches
A3: 1Y1 | B3: Line 1 | C3: 1Y1 - (SAB) | D3: SAB | E3: CAMCO | F3: E | G3: E | H3: =IF(F3&""=G3&"","✓","✗") -> ✓ | I3: N | J3: N | K3: =IF(I3&""=J3&"","✓","✗") -> ✓ | L3: 2 | M3: 2 | N3: =IF(L3&""=M3&"","✓","✗") -> ✓ | O3: 1 | P3: 1 | Q3: =IF(O3&""=P3&"","✓","✗") -> ✓ | R3: 14 | S3: 14 | T3: =IF(R3&""=S3&"","✓","✗") -> ✓ | U3: 2 | V3: 2 | W3: =IF(U3&""=V3&"","✓","✗") -> ✓ | X3: 2 | Y3: 2 | Z3: 1 | AA3: 5 | AB3: 3 | AC3: =IF(AND(X3="",AB3=0),"",N(AB3)-N(X3)) -> 1 | AD3: =COUNTIF(H3:W3,"✗") -> 0
A4: 1Z1 | B4: Line 1 | C4: 1Z1 - (DR sulaiman al habib) | D4: Dr Suliman Habib | E4: CAMCO | F4: E | G4: E | H4: =IF(F4&""=G4&"","✓","✗") -> ✓ | I4: N | J4: N | K4: =IF(I4&""=J4&"","✓","✗") -> ✓ | L4: 2 | M4: 2 | N4: =IF(L4&""=M4&"","✓","✗") -> ✓ | O4: 2 | P4: 2 | Q4: =IF(O4&""=P4&"","✓","✗") -> ✓ | R4: 20 | S4: 20 | T4: =IF(R4&""=S4&"","✓","✗") -> ✓ | U4: 4 | V4: 4 | W4: =IF(U4&""=V4&"","✓","✗") -> ✓ | X4: 2 | Y4: 2 | Z4: 0 | AA4: 4 | AB4: 4 | AC4: =IF(AND(X4="",AB4=0),"",N(AB4)-N(X4)) -> 2 | AD4: =COUNTIF(H4:W4,"✗") -> 0
A5: 1A1 | B5: Line 1 | C5: 1A1 - (KAFD) © | D5: KAFD | E5: CAMCO | F5: E | G5: E | H5: =IF(F5&""=G5&"","✓","✗") -> ✓ | I5: N | J5: N | K5: =IF(I5&""=J5&"","✓","✗") -> ✓ | L5: 4 | M5: 4 | N5: =IF(L5&""=M5&"","✓","✗") -> ✓ | O5: 2 | P5: 2 | Q5: =IF(O5&""=P5&"","✓","✗") -> ✓ | R5: 29 | S5: 29 | T5: =IF(R5&""=S5&"","✓","✗") -> ✓ | U5: 3 | V5: 3 | W5: =IF(U5&""=V5&"","✓","✗") -> ✓ | X5: 6 | Y5: 6 | Z5: 0 | AA5: 12 | AB5: 7 | AC5: =IF(AND(X5="",AB5=0),"",N(AB5)-N(X5)) -> 1 | AD5: =COUNTIF(H5:W5,"✗") -> 0
A6: 1A2 | B6: Line 1 | C6: 1A2 - (Al murooj) | D6: Al Murooj | E6: CAMCO | F6: DU | G6: DU | H6: =IF(F6&""=G6&"","✓","✗") -> ✓ | I6: N | J6: N | K6: =IF(I6&""=J6&"","✓","✗") -> ✓ | L6: 2 | M6: 2 | N6: =IF(L6&""=M6&"","✓","✗") -> ✓ | O6: 1 | P6: 1 | Q6: =IF(O6&""=P6&"","✓","✗") -> ✓ | R6: 13 | S6: 13 | T6: =IF(R6&""=S6&"","✓","✗") -> ✓ | U6: 1 | V6: 1 | W6: =IF(U6&""=V6&"","✓","✗") -> ✓ | X6: 2 | Y6: 2 | Z6: 0 | AA6: 4 | AB6: 2 | AC6: =IF(AND(X6="",AB6=0),"",N(AB6)-N(X6)) -> 0 | AD6: =COUNTIF(H6:W6,"✗") -> 0
A7: 1B1 | B7: Line 1 | C7: 1B1 - (King Fahad district) | D7: King Fahad District | E7: CAMCO | F7: DU | G7: DU | H7: =IF(F7&""=G7&"","✓","✗") -> ✓ | I7: N | J7: N | K7: =IF(I7&""=J7&"","✓","✗") -> ✓ | L7: 2 | M7: 2 | N7: =IF(L7&""=M7&"","✓","✗") -> ✓ | O7: 1 | P7: 1 | Q7: =IF(O7&""=P7&"","✓","✗") -> ✓ | R7: 13 | S7: 13 | T7: =IF(R7&""=S7&"","✓","✗") -> ✓ | U7: 1 | V7: 1 | W7: =IF(U7&""=V7&"","✓","✗") -> ✓ | X7: 2 | Y7: 2 | Z7: 0 | AA7: 4 | AB7: 2 | AC7: =IF(AND(X7="",AB7=0),"",N(AB7)-N(X7)) -> 0 | AD7: =COUNTIF(H7:W7,"✗") -> 0
A8: 1B2 | B8: Line 1 | C8: 1B2 - (King fahad district 2) | D8: King Fahad District 2 | E8: CAMCO | F8: DU | G8: DU | H8: =IF(F8&""=G8&"","✓","✗") -> ✓ | I8: N | J8: N | K8: =IF(I8&""=J8&"","✓","✗") -> ✓ | L8: 2 | M8: 2 | N8: =IF(L8&""=M8&"","✓","✗") -> ✓ | O8: 1 | P8: 1 | Q8: =IF(O8&""=P8&"","✓","✗") -> ✓ | R8: 13 | S8: 13 | T8: =IF(R8&""=S8&"","✓","✗") -> ✓ | U8: 1 | V8: 1 | W8: =IF(U8&""=V8&"","✓","✗") -> ✓ | X8: 2 | Y8: 2 | Z8: 0 | AA8: 4 | AB8: 2 | AC8: =IF(AND(X8="",AB8=0),"",N(AB8)-N(X8)) -> 0 | AD8: =COUNTIF(H8:W8,"✗") -> 0
A9: 1B3 | B9: Line 1 | C9: 1B3 - (STC) | D9: STC | E9: CAMCO | F9: DU | G9: DU | H9: =IF(F9&""=G9&"","✓","✗") -> ✓ | I9: N | J9: N | K9: =IF(I9&""=J9&"","✓","✗") -> ✓ | N9: =IF(L9&""=M9&"","✓","✗") -> ✓ | Q9: =IF(O9&""=P9&"","✓","✗") -> ✓ | T9: =IF(R9&""=S9&"","✓","✗") -> ✓ | W9: =IF(U9&""=V9&"","✓","✗") -> ✓ | AA9: 0 | AB9: 2 | AC9: =IF(AND(X9="",AB9=0),"",N(AB9)-N(X9)) -> 2 | AD9: =COUNTIF(H9:W9,"✗") -> 0
A10: 1B4 | B10: Line 1 | C10: 1B4 - (Al wurud 2) | D10: Al Wurud 2 | E10: CAMCO | F10: DU | G10: DU | H10: =IF(F10&""=G10&"","✓","✗") -> ✓ | I10: N | J10: N | K10: =IF(I10&""=J10&"","✓","✗") -> ✓ | L10: 2 | M10: 2 | N10: =IF(L10&""=M10&"","✓","✗") -> ✓ | O10: 1 | P10: 1 | Q10: =IF(O10&""=P10&"","✓","✗") -> ✓ | R10: 13 | S10: 13 | T10: =IF(R10&""=S10&"","✓","✗") -> ✓ | U10: 1 | V10: 1 | W10: =IF(U10&""=V10&"","✓","✗") -> ✓ | X10: 2 | Y10: 2 | Z10: 0 | AA10: 4 | AB10: 2 | AC10: =IF(AND(X10="",AB10=0),"",N(AB10)-N(X10)) -> 0 | AD10: =COUNTIF(H10:W10,"✗") -> 0
A11: 1C1 | B11: Line 1 | C11: 1C1 - (Al Urubah) | D11: Al Urubah | E11: CAMCO | F11: DU | G11: DU | H11: =IF(F11&""=G11&"","✓","✗") -> ✓ | I11: N | J11: N | K11: =IF(I11&""=J11&"","✓","✗") -> ✓ | L11: 2 | M11: 2 | N11: =IF(L11&""=M11&"","✓","✗") -> ✓ | O11: 1 | P11: 1 | Q11: =IF(O11&""=P11&"","✓","✗") -> ✓ | R11: 13 | S11: 13 | T11: =IF(R11&""=S11&"","✓","✗") -> ✓ | U11: 1 | V11: 1 | W11: =IF(U11&""=V11&"","✓","✗") -> ✓ | X11: 2 | Y11: 2 | Z11: 0 | AA11: 4 | AB11: 2 | AC11: =IF(AND(X11="",AB11=0),"",N(AB11)-N(X11)) -> 0 | AD11: =COUNTIF(H11:W11,"✗") -> 0
A12: 1C2 | B12: Line 1 | C12: 1C2 - (Alinma bank) | D12: Alinma bank | E12: CAMCO | F12: DU | G12: DU | H12: =IF(F12&""=G12&"","✓","✗") -> ✓ | I12: N | J12: N | K12: =IF(I12&""=J12&"","✓","✗") -> ✓ | L12: 2 | M12: 2 | N12: =IF(L12&""=M12&"","✓","✗") -> ✓ | O12: 1 | P12: 1 | Q12: =IF(O12&""=P12&"","✓","✗") -> ✓ | R12: 13 | S12: 13 | T12: =IF(R12&""=S12&"","✓","✗") -> ✓ | U12: 1 | V12: 1 | W12: =IF(U12&""=V12&"","✓","✗") -> ✓ | X12: 2 | Y12: 2 | Z12: 0 | AA12: 4 | AB12: 2 | AC12: =IF(AND(X12="",AB12=0),"",N(AB12)-N(X12)) -> 0 | AD12: =COUNTIF(H12:W12,"✗") -> 0
A13: 1C3 | B13: Line 1 | C13: 1C3 - (Bank albilad) | D13: Bank Albilad | E13: CAMCO | F13: DU | G13: DU | H13: =IF(F13&""=G13&"","✓","✗") -> ✓ | I13: N | J13: N | K13: =IF(I13&""=J13&"","✓","✗") -> ✓ | L13: 2 | M13: 2 | N13: =IF(L13&""=M13&"","✓","✗") -> ✓ | O13: 1 | P13: 1 | Q13: =IF(O13&""=P13&"","✓","✗") -> ✓ | R13: 13 | S13: 13 | T13: =IF(R13&""=S13&"","✓","✗") -> ✓ | U13: 1 | V13: 1 | W13: =IF(U13&""=V13&"","✓","✗") -> ✓ | X13: 2 | Y13: 2 | Z13: 0 | AA13: 4 | AB13: 2 | AC13: =IF(AND(X13="",AB13=0),"",N(AB13)-N(X13)) -> 0 | AD13: =COUNTIF(H13:W13,"✗") -> 0
A14: 1C4 | B14: Line 1 | C14: 1C4 - (King fahad library) | D14: King Fahad Library | E14: CAMCO | F14: DU | G14: DU | H14: =IF(F14&""=G14&"","✓","✗") -> ✓ | I14: N | J14: N | K14: =IF(I14&""=J14&"","✓","✗") -> ✓ | L14: 2 | M14: 2 | N14: =IF(L14&""=M14&"","✓","✗") -> ✓ | O14: 1 | P14: 1 | Q14: =IF(O14&""=P14&"","✓","✗") -> ✓ | R14: 13 | S14: 13 | T14: =IF(R14&""=S14&"","✓","✗") -> ✓ | U14: 1 | V14: 1 | W14: =IF(U14&""=V14&"","✓","✗") -> ✓ | X14: 2 | Y14: 2 | Z14: 0 | AA14: 4 | AB14: 2 | AC14: =IF(AND(X14="",AB14=0),"",N(AB14)-N(X14)) -> 0 | AD14: =COUNTIF(H14:W14,"✗") -> 0
A15: 1D2 | B15: Line 1 | C15: 1D2 - (Ministry of inteior) | D15: Ministry of Interior | E15: CAMCO | F15: DU | G15: DU | H15: =IF(F15&""=G15&"","✓","✗") -> ✓ | I15: N | J15: N | K15: =IF(I15&""=J15&"","✓","✗") -> ✓ | L15: 2 | M15: 2 | N15: =IF(L15&""=M15&"","✓","✗") -> ✓ | O15: 1 | P15: 1 | Q15: =IF(O15&""=P15&"","✓","✗") -> ✓ | R15: 13 | S15: 13 | T15: =IF(R15&""=S15&"","✓","✗") -> ✓ | U15: 1 | V15: 1 | W15: =IF(U15&""=V15&"","✓","✗") -> ✓ | X15: 2 | Y15: 2 | Z15: 0 | AA15: 4 | AB15: 2 | AC15: =IF(AND(X15="",AB15=0),"",N(AB15)-N(X15)) -> 0 | AD15: =COUNTIF(H15:W15,"✗") -> 0
A16: 1D5 | B16: Line 1 | C16: 1D5 - (Al muorabba) | D16: Al Muorabaa | E16: CAMCO | F16: DU | G16: DU | H16: =IF(F16&""=G16&"","✓","✗") -> ✓ | I16: N | J16: N | K16: =IF(I16&""=J16&"","✓","✗") -> ✓ | L16: 2 | M16: 2 | N16: =IF(L16&""=M16&"","✓","✗") -> ✓ | O16: 1 | P16: 1 | Q16: =IF(O16&""=P16&"","✓","✗") -> ✓ | R16: 13 | S16: 13 | T16: =IF(R16&""=S16&"","✓","✗") -> ✓ | U16: 1 | V16: 1 | W16: =IF(U16&""=V16&"","✓","✗") -> ✓ | X16: 2 | Y16: 2 | Z16: 0 | AA16: 4 | AB16: 2 | AC16: =IF(AND(X16="",AB16=0),"",N(AB16)-N(X16)) -> 0 | AD16: =COUNTIF(H16:W16,"✗") -> 0
A17: 1E2 | B17: Line 1 | C17: 1E2 - (Passport Department) | D17: Passport Department | E17: CAMCO | F17: DU | G17: DU | H17: =IF(F17&""=G17&"","✓","✗") -> ✓ | I17: N | J17: N | K17: =IF(I17&""=J17&"","✓","✗") -> ✓ | L17: 2 | M17: 2 | N17: =IF(L17&""=M17&"","✓","✗") -> ✓ | O17: 1 | P17: 1 | Q17: =IF(O17&""=P17&"","✓","✗") -> ✓ | R17: 14 | S17: 14 | T17: =IF(R17&""=S17&"","✓","✗") -> ✓ | U17: 1 | V17: 1 | W17: =IF(U17&""=V17&"","✓","✗") -> ✓ | X17: 2 | Y17: 2 | Z17: 0 | AA17: 4 | AB17: 2 | AC17: =IF(AND(X17="",AB17=0),"",N(AB17)-N(X17)) -> 0 | AD17: =COUNTIF(H17:W17,"✗") -> 0
A18: 1F4 | B18: Line 1 | C18: 1F4 - (National museum) | D18: National Museum | E18: CAMCO | F18: DU | G18: DU | H18: =IF(F18&""=G18&"","✓","✗") -> ✓ | I18: N | J18: N | K18: =IF(I18&""=J18&"","✓","✗") -> ✓ | L18: 4 | M18: 4 | N18: =IF(L18&""=M18&"","✓","✗") -> ✓ | O18: 1 | P18: 1 | Q18: =IF(O18&""=P18&"","✓","✗") -> ✓ | R18: 19 | S18: 19 | T18: =IF(R18&""=S18&"","✓","✗") -> ✓ | U18: 2 | V18: 2 | W18: =IF(U18&""=V18&"","✓","✗") -> ✓ | X18: 5 | Y18: 5 | Z18: 0 | AA18: 10 | AB18: 5 | AC18: =IF(AND(X18="",AB18=0),"",N(AB18)-N(X18)) -> 0 | AD18: =COUNTIF(H18:W18,"✗") -> 0
A19: 1F5 | B19: Line 1 | C19: 1F5 - (Al bat'ha) | D19: Al Batha | E19: CAMCO | F19: DU | G19: DU | H19: =IF(F19&""=G19&"","✓","✗") -> ✓ | I19: N | J19: N | K19: =IF(I19&""=J19&"","✓","✗") -> ✓ | L19: 2 | M19: 2 | N19: =IF(L19&""=M19&"","✓","✗") -> ✓ | O19: 1 | P19: 1 | Q19: =IF(O19&""=P19&"","✓","✗") -> ✓ | R19: 13 | S19: 13 | T19: =IF(R19&""=S19&"","✓","✗") -> ✓ | U19: 1 | V19: 1 | W19: =IF(U19&""=V19&"","✓","✗") -> ✓ | X19: 2 | Y19: 2 | Z19: 0 | AA19: 4 | AB19: 2 | AC19: =IF(AND(X19="",AB19=0),"",N(AB19)-N(X19)) -> 0 | AD19: =COUNTIF(H19:W19,"✗") -> 0
A20: 1F7 | B20: Line 1 | C20: 1F7 - (Qasr al hokm) | D20: Qasr Al Hokm | E20: CAMCO | F20: DU | G20: DU | H20: =IF(F20&""=G20&"","✓","✗") -> ✓ | I20: N | J20: N | K20: =IF(I20&""=J20&"","✓","✗") -> ✓ | N20: =IF(L20&""=M20&"","✓","✗") -> ✓ | Q20: =IF(O20&""=P20&"","✓","✗") -> ✓ | T20: =IF(R20&""=S20&"","✓","✗") -> ✓ | W20: =IF(U20&""=V20&"","✓","✗") -> ✓ | AA20: 0 | AB20: 2 | AC20: =IF(AND(X20="",AB20=0),"",N(AB20)-N(X20)) -> 2 | AD20: =COUNTIF(H20:W20,"✗") -> 0
A21: 1F8 | B21: Line 1 | C21: 1F8 - (Al owd) ‼24H | D21: Al Owd | E21: CAMCO | F21: DU | G21: DU | H21: =IF(F21&""=G21&"","✓","✗") -> ✓ | I21: Y | J21: Y | K21: =IF(I21&""=J21&"","✓","✗") -> ✓ | L21: 2 | M21: 2 | N21: =IF(L21&""=M21&"","✓","✗") -> ✓ | O21: 1 | P21: 1 | Q21: =IF(O21&""=P21&"","✓","✗") -> ✓ | R21: 11 | S21: 11 | T21: =IF(R21&""=S21&"","✓","✗") -> ✓ | U21: 1 | V21: 1 | W21: =IF(U21&""=V21&"","✓","✗") -> ✓ | X21: 1 | Y21: 1 | Z21: 1 | AA21: 3 | AB21: 3 | AC21: =IF(AND(X21="",AB21=0),"",N(AB21)-N(X21)) -> 2 | AD21: =COUNTIF(H21:W21,"✗") -> 0
A22: 1F9 | B22: Line 1 | C22: 1F9 - (Skirinah) ‼24H | D22: Skirina | E22: CAMCO | F22: E | G22: E | H22: =IF(F22&""=G22&"","✓","✗") -> ✓ | I22: Y | J22: Y | K22: =IF(I22&""=J22&"","✓","✗") -> ✓ | L22: 2 | M22: 2 | N22: =IF(L22&""=M22&"","✓","✗") -> ✓ | O22: 1 | P22: 1 | Q22: =IF(O22&""=P22&"","✓","✗") -> ✓ | R22: 14 | S22: 14 | T22: =IF(R22&""=S22&"","✓","✗") -> ✓ | U22: 2 | V22: 2 | W22: =IF(U22&""=V22&"","✓","✗") -> ✓ | X22: 1 | Y22: 1 | Z22: 1 | AA22: 3 | AB22: 3 | AC22: =IF(AND(X22="",AB22=0),"",N(AB22)-N(X22)) -> 2 | AD22: =COUNTIF(H22:W22,"✗") -> 0
A23: 1G1 | B23: Line 1 | C23: 1G1 - (Manfouhah) | D23: Manfouhah | E23: CAMCO | F23: E | G23: E | H23: =IF(F23&""=G23&"","✓","✗") -> ✓ | I23: N | J23: N | K23: =IF(I23&""=J23&"","✓","✗") -> ✓ | L23: 1 | M23: 1 | N23: =IF(L23&""=M23&"","✓","✗") -> ✓ | O23: 2 | P23: 2 | Q23: =IF(O23&""=P23&"","✓","✗") -> ✓ | R23: 24 | S23: 24 | T23: =IF(R23&""=S23&"","✓","✗") -> ✓ | U23: 4 | V23: 4 | W23: =IF(U23&""=V23&"","✓","✗") -> ✓ | X23: 2 | Y23: 2 | Z23: 0 | AA23: 4 | AB23: 4 | AC23: =IF(AND(X23="",AB23=0),"",N(AB23)-N(X23)) -> 2 | AD23: =COUNTIF(H23:W23,"✗") -> 0
A24: 1G2 | B24: Line 1 | C24: 1G2 - (Al iman hospital) | D24: Al Iman Hospital | E24: CAMCO | F24: E | G24: E | H24: =IF(F24&""=G24&"","✓","✗") -> ✓ | I24: N | J24: N | K24: =IF(I24&""=J24&"","✓","✗") -> ✓ | L24: 2 | M24: 2 | N24: =IF(L24&""=M24&"","✓","✗") -> ✓ | O24: 2 | P24: 2 | Q24: =IF(O24&""=P24&"","✓","✗") -> ✓ | R24: 20 | S24: 20 | T24: =IF(R24&""=S24&"","✓","✗") -> ✓ | U24: 4 | V24: 4 | W24: =IF(U24&""=V24&"","✓","✗") -> ✓ | X24: 2 | Y24: 2 | Z24: 0 | AA24: 4 | AB24: 4 | AC24: =IF(AND(X24="",AB24=0),"",N(AB24)-N(X24)) -> 2 | AD24: =COUNTIF(H24:W24,"✗") -> 0
A25: 1H2 | B25: Line 1 | C25: 1H2 - (Transportation Center) | D25: Transportation Center | E25: CAMCO | F25: E | G25: E | H25: =IF(F25&""=G25&"","✓","✗") -> ✓ | I25: N | J25: N | K25: =IF(I25&""=J25&"","✓","✗") -> ✓ | L25: 2 | M25: 2 | N25: =IF(L25&""=M25&"","✓","✗") -> ✓ | O25: 2 | P25: 2 | Q25: =IF(O25&""=P25&"","✓","✗") -> ✓ | R25: 20 | S25: 20 | T25: =IF(R25&""=S25&"","✓","✗") -> ✓ | U25: 4 | V25: 4 | W25: =IF(U25&""=V25&"","✓","✗") -> ✓ | X25: 3 | Y25: 3 | Z25: 1 | AA25: 7 | AB25: 5 | AC25: =IF(AND(X25="",AB25=0),"",N(AB25)-N(X25)) -> 2 | AD25: =COUNTIF(H25:W25,"✗") -> 0
A26: 1J1 | B26: Line 1 | C26: 1J1 - (Al aziziah) | D26: Al Aziziah | E26: CAMCO | F26: E | G26: E | H26: =IF(F26&""=G26&"","✓","✗") -> ✓ | I26: N | J26: N | K26: =IF(I26&""=J26&"","✓","✗") -> ✓ | L26: 2 | M26: 2 | N26: =IF(L26&""=M26&"","✓","✗") -> ✓ | O26: 2 | P26: 2 | Q26: =IF(O26&""=P26&"","✓","✗") -> ✓ | R26: 20 | S26: 20 | T26: =IF(R26&""=S26&"","✓","✗") -> ✓ | U26: 4 | V26: 4 | W26: =IF(U26&""=V26&"","✓","✗") -> ✓ | X26: 2 | Y26: 2 | Z26: 0 | AA26: 4 | AB26: 4 | AC26: =IF(AND(X26="",AB26=0),"",N(AB26)-N(X26)) -> 2 | AD26: =COUNTIF(H26:W26,"✗") -> 0
A27: 1J2 | B27: Line 1 | C27: 1J2 - (Ad dar al bida) | D27: Ad Dar Al Baida | E27: CAMCO | F27: E | G27: E | H27: =IF(F27&""=G27&"","✓","✗") -> ✓ | I27: N | J27: N | K27: =IF(I27&""=J27&"","✓","✗") -> ✓ | L27: 2 | M27: 2 | N27: =IF(L27&""=M27&"","✓","✗") -> ✓ | O27: 2 | P27: 2 | Q27: =IF(O27&""=P27&"","✓","✗") -> ✓ | R27: 20 | S27: 20 | T27: =IF(R27&""=S27&"","✓","✗") -> ✓ | U27: 4 | V27: 4 | W27: =IF(U27&""=V27&"","✓","✗") -> ✓ | X27: 3 | Y27: 3 | Z27: 1 | AA27: 7 | AB27: 5 | AC27: =IF(AND(X27="",AB27=0),"",N(AB27)-N(X27)) -> 2 | AD27: =COUNTIF(H27:W27,"✗") -> 0
A28: 2A1 | B28: Line 2 | C28: 2A1 - (King saud University) ‼24H | D28: King Saud University | E28: CAMCO | F28: E | G28: E | H28: =IF(F28&""=G28&"","✓","✗") -> ✓ | I28: Y | J28: Y | K28: =IF(I28&""=J28&"","✓","✗") -> ✓ | L28: 2 | M28: 2 | N28: =IF(L28&""=M28&"","✓","✗") -> ✓ | O28: 2 | P28: 2 | Q28: =IF(O28&""=P28&"","✓","✗") -> ✓ | R28: 20 | S28: 20 | T28: =IF(R28&""=S28&"","✓","✗") -> ✓ | U28: 4 | V28: 4 | W28: =IF(U28&""=V28&"","✓","✗") -> ✓ | X28: 2 | Y28: 2 | Z28: 1 | AA28: 5 | AB28: 5 | AC28: =IF(AND(X28="",AB28=0),"",N(AB28)-N(X28)) -> 3 | AD28: =COUNTIF(H28:W28,"✗") -> 0
A29: 2A2 | B29: Line 2 | C29: 2A2 - (King Salman oasis) | D29: King Salman Oasis | E29: CAMCO | F29: E | G29: E | H29: =IF(F29&""=G29&"","✓","✗") -> ✓ | I29: N | J29: N | K29: =IF(I29&""=J29&"","✓","✗") -> ✓ | L29: 2 | M29: 2 | N29: =IF(L29&""=M29&"","✓","✗") -> ✓ | O29: 1 | P29: 1 | Q29: =IF(O29&""=P29&"","✓","✗") -> ✓ | R29: 14 | S29: 14 | T29: =IF(R29&""=S29&"","✓","✗") -> ✓ | U29: 2 | V29: 2 | W29: =IF(U29&""=V29&"","✓","✗") -> ✓ | X29: 1 | Y29: 1 | Z29: 0 | AA29: 2 | AB29: 2 | AC29: =IF(AND(X29="",AB29=0),"",N(AB29)-N(X29)) -> 1 | AD29: =COUNTIF(H29:W29,"✗") -> 0
A30: 2A3 | B30: Line 2 | C30: 2A3 - (KACST) | D30: KACST | E30: CAMCO | F30: SU | G30: SU | H30: =IF(F30&""=G30&"","✓","✗") -> ✓ | I30: N | J30: N | K30: =IF(I30&""=J30&"","✓","✗") -> ✓ | L30: 1 | M30: 1 | N30: =IF(L30&""=M30&"","✓","✗") -> ✓ | O30: 2 | P30: 2 | Q30: =IF(O30&""=P30&"","✓","✗") -> ✓ | R30: 16 | S30: 16 | T30: =IF(R30&""=S30&"","✓","✗") -> ✓ | U30: 4 | V30: 4 | W30: =IF(U30&""=V30&"","✓","✗") -> ✓ | X30: 2 | Y30: 2 | Z30: 0 | AA30: 4 | AB30: 4 | AC30: =IF(AND(X30="",AB30=0),"",N(AB30)-N(X30)) -> 2 | AD30: =COUNTIF(H30:W30,"✗") -> 0
A31: 2B1 | B31: Line 2 | C31: 2B1 - (Takhasusi road) | D31: At Takhassussi | E31: CAMCO | F31: SU | G31: SU | H31: =IF(F31&""=G31&"","✓","✗") -> ✓ | I31: N | J31: N | K31: =IF(I31&""=J31&"","✓","✗") -> ✓ | L31: 1 | M31: 1 | N31: =IF(L31&""=M31&"","✓","✗") -> ✓ | O31: 2 | P31: 2 | Q31: =IF(O31&""=P31&"","✓","✗") -> ✓ | R31: 16 | S31: 16 | T31: =IF(R31&""=S31&"","✓","✗") -> ✓ | U31: 4 | V31: 4 | W31: =IF(U31&""=V31&"","✓","✗") -> ✓ | X31: 2 | Y31: 2 | Z31: 0 | AA31: 4 | AB31: 4 | AC31: =IF(AND(X31="",AB31=0),"",N(AB31)-N(X31)) -> 2 | AD31: =COUNTIF(H31:W31,"✗") -> 0
A32: 2B2 | B32: Line 2 | C32: 2B2 - (STC) © | D32: STC | E32: CAMCO | F32: DU | G32: DU | H32: =IF(F32&""=G32&"","✓","✗") -> ✓ | I32: N | J32: N | K32: =IF(I32&""=J32&"","✓","✗") -> ✓ | L32: 4 | M32: 4 | N32: =IF(L32&""=M32&"","✓","✗") -> ✓ | O32: 2 | P32: 2 | Q32: =IF(O32&""=P32&"","✓","✗") -> ✓ | R32: 22 | S32: 22 | T32: =IF(R32&""=S32&"","✓","✗") -> ✓ | U32: 2 | V32: 2 | W32: =IF(U32&""=V32&"","✓","✗") -> ✓ | X32: 5 | Y32: 5 | Z32: 0 | AA32: 10 | AB32: 6 | AC32: =IF(AND(X32="",AB32=0),"",N(AB32)-N(X32)) -> 1 | AD32: =COUNTIF(H32:W32,"✗") -> 0
... A45: 3B1 | B45: Line 3 | C45: 3B1 - (Ad Douh) | D45: Ad Douh | E45: FLOW | F45: E | G45: E | H45: =IF(F45&""=G45&"","✓","✗") -> ✓ | I45: N | J45: N | K45: =IF(I45&""=J45&"","✓","✗") -> ✓ | L45: 2 | M45: 2 | N45: =IF(L45&""=M45&"","✓","✗") -> ✓ | O45: 2 | P45: 2 | Q45: =IF(O45&""=P45&"","✓","✗") -> ✓ | R45: 20 | S45: 20 | T45: =IF(R45&""=S45&"","✓","✗") -> ✓ | U45: 4 | V45: 2 | W45: =IF(U45&""=V45&"","✓","✗") -> ✗ | X45: 2 | Y45: 2 | Z45: 0 | AA45: 4 | AB45: 2 | AC45: =IF(AND(X45="",AB45=0),"",N(AB45)-N(X45)) -> 0 | AD45: =COUNTIF(H45:W45,"✗") -> 1
A46: 3B2 | B46: Line 3 | C46: 3B2 - (Wesern Station) © | D46: Western Station | E46: FLOW | F46: E | G46: E | H46: =IF(F46&""=G46&"","✓","✗") -> ✓ | I46: N | J46: N | K46: =IF(I46&""=J46&"","✓","✗") -> ✓ | L46: 2 | M46: 2 | N46: =IF(L46&""=M46&"","✓","✗") -> ✓ | P46: 2 | Q46: =IF(O46&""=P46&"","✓","✗") -> ✗ | S46: 16 | T46: =IF(R46&""=S46&"","✓","✗") -> ✗ | V46: 1 | W46: =IF(U46&""=V46&"","✓","✗") -> ✗ | X46: 5 | Y46: 5 | Z46: 0 | AA46: 10 | AB46: 4 | AC46: =IF(AND(X46="",AB46=0),"",N(AB46)-N(X46)) -> -1 | AD46: =COUNTIF(H46:W46,"✗") -> 3
A47: 3C2 | B47: Line 3 | C47: 3C2 - (Aishah Bint abi bakr st) | D47: Aisha Bin Abi Bakr Street | E47: FLOW | F47: E | G47: E | H47: =IF(F47&""=G47&"","✓","✗") -> ✓ | I47: N | J47: N | K47: =IF(I47&""=J47&"","✓","✗") -> ✓ | L47: 2 | M47: 2 | N47: =IF(L47&""=M47&"","✓","✗") -> ✓ | O47: 2 | P47: 2 | Q47: =IF(O47&""=P47&"","✓","✗") -> ✓ | R47: 20 | S47: 20 | T47: =IF(R47&""=S47&"","✓","✗") -> ✓ | U47: 4 | V47: 2 | W47: =IF(U47&""=V47&"","✓","✗") -> ✗ | X47: 2 | Y47: 2 | Z47: 0 | AA47: 4 | AB47: 2 | AC47: =IF(AND(X47="",AB47=0),"",N(AB47)-N(X47)) -> 0 | AD47: =COUNTIF(H47:W47,"✗") -> 1
A48: 3D3 | B48: Line 3 | C48: 3D3 - (Dhahrat al badiah) | D48: Dharat Al Badiah | E48: FLOW | F48: E | G48: E | H48: =IF(F48&""=G48&"","✓","✗") -> ✓ | I48: N | J48: N | K48: =IF(I48&""=J48&"","✓","✗") -> ✓ | L48: 2 | M48: 2 | N48: =IF(L48&""=M48&"","✓","✗") -> ✓ | O48: 2 | P48: 2 | Q48: =IF(O48&""=P48&"","✓","✗") -> ✓ | R48: 20 | S48: 20 | T48: =IF(R48&""=S48&"","✓","✗") -> ✓ | U48: 4 | V48: 2 | W48: =IF(U48&""=V48&"","✓","✗") -> ✗ | X48: 2 | Y48: 2 | Z48: 0 | AA48: 4 | AB48: 2 | AC48: =IF(AND(X48="",AB48=0),"",N(AB48)-N(X48)) -> 0 | AD48: =COUNTIF(H48:W48,"✗") -> 1
A49: 3D1 | B49: Line 3 | C49: 3D1 - (Sultanah) | D49: Sultanah | E49: FLOW | F49: E | G49: E | H49: =IF(F49&""=G49&"","✓","✗") -> ✓ | I49: N | J49: N | K49: =IF(I49&""=J49&"","✓","✗") -> ✓ | L49: 1 | M49: 1 | N49: =IF(L49&""=M49&"","✓","✗") -> ✓ | O49: 2 | P49: 2 | Q49: =IF(O49&""=P49&"","✓","✗") -> ✓ | R49: 20 | S49: 20 | T49: =IF(R49&""=S49&"","✓","✗") -> ✓ | U49: 4 | V49: 2 | W49: =IF(U49&""=V49&"","✓","✗") -> ✗ | X49: 3 | Y49: 3 | Z49: 1 | AA49: 7 | AB49: 3 | AC49: =IF(AND(X49="",AB49=0),"",N(AB49)-N(X49)) -> 0 | AD49: =COUNTIF(H49:W49,"✗") -> 1
A50: 3D2 | B50: Line 3 | C50: 3D2 - (Aljarradiyah) | D50: Al Jarradiyah | E50: FLOW | F50: E | G50: E | H50: =IF(F50&""=G50&"","✓","✗") -> ✓ | I50: N | J50: N | K50: =IF(I50&""=J50&"","✓","✗") -> ✓ | L50: 2 | M50: 2 | N50: =IF(L50&""=M50&"","✓","✗") -> ✓ | O50: 2 | P50: 2 | Q50: =IF(O50&""=P50&"","✓","✗") -> ✓ | R50: 20 | S50: 20 | T50: =IF(R50&""=S50&"","✓","✗") -> ✓ | U50: 4 | V50: 2 | W50: =IF(U50&""=V50&"","✓","✗") -> ✗ | X50: 2 | Y50: 2 | Z50: 0 | AA50: 4 | AB50: 2 | AC50: =IF(AND(X50="",AB50=0),"",N(AB50)-N(X50)) -> 0 | AD50: =COUNTIF(H50:W50,"✗") -> 1
A51: 3E1 | B51: Line 3 | C51: 3E1 - (Courts Complex) | D51: Courts Complex | E51: FLOW | F51: DU | G51: DU | H51: =IF(F51&""=G51&"","✓","✗") -> ✓ | I51: N | J51: N | K51: =IF(I51&""=J51&"","✓","✗") -> ✓ | L51: 2 | M51: 2 | N51: =IF(L51&""=M51&"","✓","✗") -> ✓ | O51: 1 | P51: 1 | Q51: =IF(O51&""=P51&"","✓","✗") -> ✓ | R51: 8 | S51: 8 | T51: =IF(R51&""=S51&"","✓","✗") -> ✓ | U51: 2 | V51: 1 | W51: =IF(U51&""=V51&"","✓","✗") -> ✗ | X51: 1 | Y51: 1 | Z51: 0 | AA51: 2 | AB51: 1 | AC51: =IF(AND(X51="",AB51=0),"",N(AB51)-N(X51)) -> 0 | AD51: =COUNTIF(H51:W51,"✗") -> 1
A52: 3E2 | B52: Line 3 | C52: 3E2 - (Qasr Al Hokm) © | D52: Qasr Al Hokm | E52: FLOW | F52: DU | G52: DU | H52: =IF(F52&""=G52&"","✓","✗") -> ✓ | I52: N | J52: N | K52: =IF(I52&""=J52&"","✓","✗") -> ✓ | L52: 4 | M52: 2 | N52: =IF(L52&""=M52&"","✓","✗") -> ✗ | O52: 2 | P52: 2 | Q52: =IF(O52&""=P52&"","✓","✗") -> ✓ | R52: 42 | S52: 42 | T52: =IF(R52&""=S52&"","✓","✗") -> ✓ | U52: 2 | V52: 2 | W52: =IF(U52&""=V52&"","✓","✗") -> ✓ | X52: 4 | Y52: 4 | Z52: 0 | AA52: 8 | AB52: 5 | AC52: =IF(AND(X52="",AB52=0),"",N(AB52)-N(X52)) -> 1 | AD52: =COUNTIF(H52:W52,"✗") -> 1
...

Sheet P&R
A1: Station | B1: Stations file (P&R) | C1: OMC file (P&R row) | D1: Match
A2: 1H2 | B2: Y | C2: Y | D2: =IF(B2=C2,"✓","✗") -> ✓
A3: 1J2 | B3: Y | C3: Y | D3: =IF(B3=C3,"✓","✗") -> ✓
A4: 1Y1 | B4: Y | C4: Y | D4: =IF(B4=C4,"✓","✗") -> ✓
A5: 2G1 | B5: Y | C5: Y | D5: =IF(B5=C5,"✓","✗") -> ✓
A6: 3A1 | B6: Y | C6: Y | D6: =IF(B6=C6,"✓","✗") -> ✓
A7: 3B2 | B7: N | C7: Y | D7: =IF(B7=C7,"✓","✗") -> ✗
A8: 3D1 | B8: Y | C8: Y | D8: =IF(B8=C8,"✓","✗") -> ✓
A9: 3E2 | B9: N | C9: Y | D9: =IF(B9=C9,"✓","✗") -> ✗
A10: 3F2 | B10: N | C10: Y | D10: =IF(B10=C10,"✓","✗") -> ✗
A11: 3G2 | B11: Y | C11: Y | D11: =IF(B11=C11,"✓","✗") -> ✓
A12: 3J1 | B12: N | C12: Y | D12: =IF(B12=C12,"✓","✗") -> ✗
A13: 3K1 | B13: Y | C13: Y | D13: =IF(B13=C13,"✓","✗") -> ✓
... A16: 6F1 | B16: Y | C16: Y | D16: =IF(B16=C16,"✓","✗") -> ✓
A18: OMC lists 6-4 @ 6H2/3J1 (shown as 3J1) and 3-6 'Integrated with 3E2'.

Sheet Data Issues
A1: File | B1: Location | C1: Issue
A2: OMC – FLOW | B2: Line 6 section | C2: Rows 4B1 and 4C1 (Line 4 stations) repeated with zero staff and 24h = N, while they are 24H stations
A3: OMC – FLOW | B3: Line 3-6 header | C3: AFC column labelled 'Ticket Barriers' instead of 'AFC Bank No.' (counts are half of Stations file)
A4: Both | B4: 5A2 | C4: Name: 'MEW&A' (Stations) vs 'King Abdulaziz Hospital' (OMC)
A5: Stations | B5: 3B2, 3J2 | C5: Ticket Office / AFC data missing, available in OMC file
A6: Stations | B6: 4A1, 6H2 | C6: Platforms missing (OMC = 2)
A7: Stations | B7: Spelling | C7: 'Wesern Station', 'Treminal 3-4', 'Ministry of inteior'
A8: Both | B8: Line 5 AFC Total | C8: 5C1/5B3 = 10 vs 8 and 5B1/5A5 = 8 vs 10 – values look swapped
A9: Both | B9: Guest stations 1B3, 1F7 | C9: Stations file: 0 guards; OMC: 2 guards per shift
