Workbook

Sheet طريقة الاستخدام
B1: رائحة أمي — نظام المخزون والوصفات والإنتاج
B4: دليل الألوان
B5: خانة صفراء | C5: تكتب فيها أنت.
B6: خانة رمادية | C6: معادلة تلقائية. لا تكتب فيها.
B7: نص أزرق | C7: بيانات مبدئية مدخلة (أسعارك، والوصفة اللي عطيتني). عدّلها براحتك.
B9: الإعداد لأول مرة (مرة وحدة)
B10: 1. المواد الخام | C10: عدّل القائمة المبدئية: أضف كل مادة تستخدمها بكود ثابت (RM للخام، PK للتغليف) ووحدتها. اكتب الرصيد الافتتاحي اللي عندك الحين بعد ما توزنه.
B11: 2. المنتجات | C11: الأسعار مدخلة. اكتب «إنتاج التشغيلة» لكل منتج: كم حبة تطلع من خلطة وحدة. واكتب رصيد افتتاحي للجاهز وحد إعادة الإنتاج.
B12: 3. الوصفات | C12: لكل منتج اكتب مكوناته سطر سطر. مثال المخصوص مدخل: 10000 جرام بودرة عود + 30 جرام زيت لكل تشغيلة، وعلبة + ملصق لكل حبة.
B14: الاستخدام اليومي
B15: اشتريت مواد | C15: صفحة «حركة المخزون»: النوع «وارد شراء»، الكود، الكمية بالجرام أو المل أو الحبة، والمبلغ المدفوع كامل. مثال: 2026-10-20 | وارد شراء | RM-001 | 10000 | 3500 | مورد فلان.
B16: خلطت تشغيلة | C16: صفحة «الإنتاج»: التاريخ، رقم التشغيلة، كود المنتج، عدد التشغيلات، والعدد الفعلي. مثال: 2026-10-21 | MA-02-261021 | MA-02 | 1 | 98. المواد تنخصم تلقائياً والمنتج الجاهز يزيد.
B17: بعت طلب | C17: صفحة «المبيعات»: سطر لكل منتج في الطلب. مثال: 2026-10-22 | 1001 | إنستقرام | MA-02 | 2 | خصم 0 | الرياض.
B18: تالف أو عينة أو هدية | C18: صفحة «حركة المخزون» بالنوع المناسب، عشان الرصيد يبقى صحيح.
B20: الجرد الشهري
B21: آخر كل شهر | C21: صفحة «الجرد»: اكتب كل كود والوزن أو العدد الفعلي. النظام يطلع الفرق، وتسجله كـ«تسوية زيادة» أو «تسوية نقص» في حركة المخزون.
B23: قواعد ذهبية
B24: الوحدة الأساسية | C24: كل شي بالجرام أو المل أو الحبة. 10 كجم تُكتب 10000. لا تخلط كيلو مع جرام.
B25: الكود ثابت | C25: لا تغيّر كود مادة أو منتج بعد ما تبدأ تسجل عليه. إذا وقفت منتج اتركه بدون حذف.
B26: رقم التشغيلة | C26: يُطبع على ملصق كل منتج. إذا اشتكى عميل تعرف من أي خلطة طلع المنتج.
B27: سجّل في نفس اليوم | C27: التأخير في التسجيل هو أكبر سبب لخراب أي جرد.

Sheet الملخص
A1: رائحة أمي — لوحة الملخص
A2: كل الأرقام هنا تلقائية. لا تكتب في هذي الصفحة.
D3: الفئة | E3: الكمية المباعة | F3: المبيعات | G3: الربح | H3: هامش الربح
A4: إجمالي المبيعات | B4: =SUM(المبيعات!$J$5:$J$1004) -> 0 | D4: =الإعدادات!E5 -> معمول | E4: =SUMIFS(المبيعات!$G$5:$G$1004,المبيعات!$F$5:$F$1004,D4) -> 0 | F4: =SUMIFS(المبيعات!$J$5:$J$1004,المبيعات!$F$5:$F$1004,D4) -> 0 | G4: =SUMIFS(المبيعات!$L$5:$L$1004,المبيعات!$F$5:$F$1004,D4) -> 0 | H4: =IFERROR(G4/F4,0) -> 0
A5: إجمالي الربح (قبل المصاريف) | B5: =SUM(المبيعات!$L$5:$L$1004) -> 0 | D5: =الإعدادات!E6 -> عود | E5: =SUMIFS(المبيعات!$G$5:$G$1004,المبيعات!$F$5:$F$1004,D5) -> 0 | F5: =SUMIFS(المبيعات!$J$5:$J$1004,المبيعات!$F$5:$F$1004,D5) -> 0 | G5: =SUMIFS(المبيعات!$L$5:$L$1004,المبيعات!$F$5:$F$1004,D5) -> 0 | H5: =IFERROR(G5/F5,0) -> 0
A6: هامش الربح | B6: =IFERROR(B5/B4,0) -> 0 | D6: =الإعدادات!E7 -> مرشات | E6: =SUMIFS(المبيعات!$G$5:$G$1004,المبيعات!$F$5:$F$1004,D6) -> 0 | F6: =SUMIFS(المبيعات!$J$5:$J$1004,المبيعات!$F$5:$F$1004,D6) -> 0 | G6: =SUMIFS(المبيعات!$L$5:$L$1004,المبيعات!$F$5:$F$1004,D6) -> 0 | H6: =IFERROR(G6/F6,0) -> 0
A7: عدد الطلبات | B7: =SUMPRODUCT((المبيعات!$B$5:$B$1004<>"")/COUNTIF(المبيعات!$B$5:$B$1004,المبيعات!$B$5:$B$1004&"")) -> 0 | D7: =الإعدادات!E8 -> أدهان | E7: =SUMIFS(المبيعات!$G$5:$G$1004,المبيعات!$F$5:$F$1004,D7) -> 0 | F7: =SUMIFS(المبيعات!$J$5:$J$1004,المبيعات!$F$5:$F$1004,D7) -> 0 | G7: =SUMIFS(المبيعات!$L$5:$L$1004,المبيعات!$F$5:$F$1004,D7) -> 0 | H7: =IFERROR(G7/F7,0) -> 0
A8: متوسط قيمة الطلب | B8: =IFERROR(B4/B7,0) -> 0
A9: قيمة مخزون المواد والتغليف | B9: =SUM('المواد الخام'!$O$5:$O$104) -> 0
A10: مواد تحتاج طلب | B10: =COUNTIF('المواد الخام'!$N$5:$N$104,"اطلب الآن")+COUNTIF('المواد الخام'!$N$5:$N$104,"نفد") -> 0
A11: منتجات تحتاج إنتاج | B11: =COUNTIF(المنتجات!$R$5:$R$24,"أعد الإنتاج")+COUNTIF(المنتجات!$R$5:$R$24,"نفد") -> 0
A14: المنتجات: الربحية والمخزون
A15: المنتج | B15: سعر البيع | D15: تكلفة الحبة | E15: هامش الربح | F15: المباع | G15: الرصيد | H15: الحالة
A16: =IF(المنتجات!$A5="","",المنتجات!C5) -> معمول الملكي | B16: =IF(المنتجات!$A5="","",المنتجات!F5) -> 130 | D16: =IF(المنتجات!$A5="","",المنتجات!H5) -> 0 | E16: =IF(المنتجات!$A5="","",المنتجات!J5) -> 1 | F16: =IF(المنتجات!$A5="","",المنتجات!N5) -> 0 | G16: =IF(المنتجات!$A5="","",المنتجات!P5) -> 0 | H16: =IF(المنتجات!$A5="","",المنتجات!R5) -> لم يُسجل رصيد
A17: =IF(المنتجات!$A6="","",المنتجات!C6) -> معمول المخصوص (الدوسري) | B17: =IF(المنتجات!$A6="","",المنتجات!F6) -> 250 | D17: =IF(المنتجات!$A6="","",المنتجات!H6) -> 0 | E17: =IF(المنتجات!$A6="","",المنتجات!J6) -> 1 | F17: =IF(المنتجات!$A6="","",المنتجات!N6) -> 0 | G17: =IF(المنتجات!$A6="","",المنتجات!P6) -> 0 | H17: =IF(المنتجات!$A6="","",المنتجات!R6) -> لم يُسجل رصيد
A18: =IF(المنتجات!$A7="","",المنتجات!C7) -> معمول العرايسي | B18: =IF(المنتجات!$A7="","",المنتجات!F7) -> 120 | D18: =IF(المنتجات!$A7="","",المنتجات!H7) -> 0 | E18: =IF(المنتجات!$A7="","",المنتجات!J7) -> 1 | F18: =IF(المنتجات!$A7="","",المنتجات!N7) -> 0 | G18: =IF(المنتجات!$A7="","",المنتجات!P7) -> 0 | H18: =IF(المنتجات!$A7="","",المنتجات!R7) -> لم يُسجل رصيد
A19: =IF(المنتجات!$A8="","",المنتجات!C8) -> عود مسقى | B19: =IF(المنتجات!$A8="","",المنتجات!F8) -> 95 | D19: =IF(المنتجات!$A8="","",المنتجات!H8) -> 0 | E19: =IF(المنتجات!$A8="","",المنتجات!J8) -> 1 | F19: =IF(المنتجات!$A8="","",المنتجات!N8) -> 0 | G19: =IF(المنتجات!$A8="","",المنتجات!P8) -> 0 | H19: =IF(المنتجات!$A8="","",المنتجات!R8) -> لم يُسجل رصيد
A20: =IF(المنتجات!$A9="","",المنتجات!C9) -> عود طبيعي مسقى زيوت | B20: =IF(المنتجات!$A9="","",المنتجات!F9) -> 250 | D20: =IF(المنتجات!$A9="","",المنتجات!H9) -> 0 | E20: =IF(المنتجات!$A9="","",المنتجات!J9) -> 1 | F20: =IF(المنتجات!$A9="","",المنتجات!N9) -> 0 | G20: =IF(المنتجات!$A9="","",المنتجات!P9) -> 0 | H20: =IF(المنتجات!$A9="","",المنتجات!R9) -> لم يُسجل رصيد
A21: =IF(المنتجات!$A10="","",المنتجات!C10) -> مرش أسيل | B21: =IF(المنتجات!$A10="","",المنتجات!F10) -> 80 | D21: =IF(المنتجات!$A10="","",المنتجات!H10) -> 0 | E21: =IF(المنتجات!$A10="","",المنتجات!J10) -> 1 | F21: =IF(المنتجات!$A10="","",المنتجات!N10) -> 0 | G21: =IF(المنتجات!$A10="","",المنتجات!P10) -> 0 | H21: =IF(المنتجات!$A10="","",المنتجات!R10) -> لم يُسجل رصيد
A22: =IF(المنتجات!$A11="","",المنتجات!C11) -> مرش شهد | B22: =IF(المنتجات!$A11="","",المنتجات!F11) -> 80 | D22: =IF(المنتجات!$A11="","",المنتجات!H11) -> 0 | E22: =IF(المنتجات!$A11="","",المنتجات!J11) -> 1 | F22: =IF(المنتجات!$A11="","",المنتجات!N11) -> 0 | G22: =IF(المنتجات!$A11="","",المنتجات!P11) -> 0 | H22: =IF(المنتجات!$A11="","",المنتجات!R11) -> لم يُسجل رصيد
A23: =IF(المنتجات!$A12="","",المنتجات!C12) -> مرش سديم | B23: =IF(المنتجات!$A12="","",المنتجات!F12) -> 80 | D23: =IF(المنتجات!$A12="","",المنتجات!H12) -> 0 | E23: =IF(المنتجات!$A12="","",المنتجات!J12) -> 1 | F23: =IF(المنتجات!$A12="","",المنتجات!N12) -> 0 | G23: =IF(المنتجات!$A12="","",المنتجات!P12) -> 0 | H23: =IF(المنتجات!$A12="","",المنتجات!R12) -> لم يُسجل رصيد
A24: =IF(المنتجات!$A13="","",المنتجات!C13) -> فتشة العروس | B24: =IF(المنتجات!$A13="","",المنتجات!F13) -> 70 | D24: =IF(المنتجات!$A13="","",المنتجات!H13) -> 0 | E24: =IF(المنتجات!$A13="","",المنتجات!J13) -> 1 | F24: =IF(المنتجات!$A13="","",المنتجات!N13) -> 0 | G24: =IF(المنتجات!$A13="","",المنتجات!P13) -> 0 | H24: =IF(المنتجات!$A13="","",المنتجات!R13) -> لم يُسجل رصيد
A25: =IF(المنتجات!$A14="","",المنتجات!C14) -> خمرية الزعفران | B25: =IF(المنتجات!$A14="","",المنتجات!F14) -> 60 | D25: =IF(المنتجات!$A14="","",المنتجات!H14) -> 0 | E25: =IF(المنتجات!$A14="","",المنتجات!J14) -> 1 | F25: =IF(المنتجات!$A14="","",المنتجات!N14) -> 0 | G25: =IF(المنتجات!$A14="","",المنتجات!P14) -> 0 | H25: =IF(المنتجات!$A14="","",المنتجات!R14) -> لم يُسجل رصيد
A26: =IF(المنتجات!$A15="","",المنتجات!C15) -> خمرية المسك | B26: =IF(المنتجات!$A15="","",المنتجات!F15) -> 60 | D26: =IF(المنتجات!$A15="","",المنتجات!H15) -> 0 | E26: =IF(المنتجات!$A15="","",المنتجات!J15) -> 1 | F26: =IF(المنتجات!$A15="","",المنتجات!N15) -> 0 | G26: =IF(المنتجات!$A15="","",المنتجات!P15) -> 0 | H26: =IF(المنتجات!$A15="","",المنتجات!R15) -> لم يُسجل رصيد
A27: =IF(المنتجات!$A16="","",المنتجات!C16) -> دهن العود الطبيعي | B27: =IF(المنتجات!$A16="","",المنتجات!F16) -> 120 | D27: =IF(المنتجات!$A16="","",المنتجات!H16) -> 0 | E27: =IF(المنتجات!$A16="","",المنتجات!J16) -> 1 | F27: =IF(المنتجات!$A16="","",المنتجات!N16) -> 0 | G27: =IF(المنتجات!$A16="","",المنتجات!P16) -> 0 | H27: =IF(المنتجات!$A16="","",المنتجات!R16) -> لم يُسجل رصيد
... A35: =IF(المنتجات!$A24="","",المنتجات!C24) | B35: =IF(المنتجات!$A24="","",المنتجات!F24) | D35: =IF(المنتجات!$A24="","",المنتجات!H24) | E35: =IF(المنتجات!$A24="","",المنتجات!J24) | F35: =IF(المنتجات!$A24="","",المنتجات!N24) | G35: =IF(المنتجات!$A24="","",المنتجات!P24) | H35: =IF(المنتجات!$A24="","",المنتجات!R24)

Sheet المنتجات
A1: المنتجات والأسعار
A2: كل منتج بكود ثابت. التكلفة تُحسب تلقائياً من صفحة الوصفات، والرصيد من الإنتاج والمبيعات وحركة المخزون. «إنتاج التشغيلة» = كم حبة تطلع من تشغيلة وحدة حسب الوصفة.
A4: الكود | B4: الفئة | C4: اسم المنتج | D4: الحجم | E4: الوحدة | F4: سعر البيع (ر.س) | G4: إنتاج التشغيلة (حبة) | H4: تكلفة الحبة | I4: الربح للحبة | J4: هامش الربح | K4: السعر لكل جرام / مل | L4: رصيد افتتاحي | M4: المُنتَج | N4: المباع | O4: خروج آخر (تالف / عينات / تسوية) | P4: الرصيد الحالي | Q4: حد إعادة الإنتاج | R4: الحالة | S4: إجمالي المبيعات | T4: ملاحظات
A5: MA-01 | B5: معمول | C5: معمول الملكي | D5: 80 | E5: جرام | F5: 130 | H5: =IF($A5="","",SUMIFS(الوصفات!$J$5:$J$304,الوصفات!$A$5:$A$304,$A5)) -> 0 | I5: =IF($A5="","",F5-H5) -> 130 | J5: =IF($A5="","",IFERROR(I5/F5,0)) -> 1 | K5: =IF($A5="","",IFERROR(F5/(D5*IF(E5="تولة",الإعدادات!$C$5,1)),0)) -> 1.625 | M5: =IF($A5="","",SUMIFS(الإنتاج!$G$5:$G$504,الإنتاج!$C$5:$C$504,$A5)) -> 0 | N5: =IF($A5="","",SUMIFS(المبيعات!$G$5:$G$1004,المبيعات!$D$5:$D$1004,$A5)) -> 0 | O5: =IF($A5="","",SUMIFS('حركة المخزون'!$E$5:$E$1004,'حركة المخزون'!$C$5:$C$1004,$A5,'حركة المخزون'!$B$5:$B$1004,"تالف")+SUMIFS('حركة المخزون'!$E$5:$E$1004,'حركة المخزون'!$C$5:$C$1004,$A5,'حركة المخزون'!$B$5:$B$1004,"عينة / هدية")+SUMIFS('حركة المخزون'!$E$5:$E$1004,'حركة المخزون'!$C$5:$C$1004,$A5,'حركة المخزون'!$B$5:$B$1004,"تسوية نقص")-SUMIFS('حركة المخزون'!$E$5:$E$1004,'حركة المخزون'!$C$5:$C$1004,$A5,'حركة المخزون'!$B$5:$B$1004,"تسوية زيادة")) -> 0 | P5: =IF($A5="","",N(L5)+M5-N5-O5) -> 0 | R5: =IF($A5="","",IF(AND(L5="",M5=0,N5=0),"لم يُسجل رصيد",IF(P5<=0,"نفد",IF(P5<=N(Q5),"أعد الإنتاج","متوفر")))) -> لم يُسجل رصيد | S5: =IF($A5="","",SUMIFS(المبيعات!$J$5:$J$1004,المبيعات!$D$5:$D$1004,$A5)) -> 0
A6: MA-02 | B6: معمول | C6: معمول المخصوص (الدوسري) | D6: 100 | E6: جرام | F6: 250 | G6: 100 | H6: =IF($A6="","",SUMIFS(الوصفات!$J$5:$J$304,الوصفات!$A$5:$A$304,$A6)) -> 0 | I6: =IF($A6="","",F6-H6) -> 250 | J6: =IF($A6="","",IFERROR(I6/F6,0)) -> 1 | K6: =IF($A6="","",IFERROR(F6/(D6*IF(E6="تولة",الإعدادات!$C$5,1)),0)) -> 2.5 | M6: =IF($A6="","",SUMIFS(الإنتاج!$G$5:$G$504,الإنتاج!$C$5:$C$504,$A6)) -> 0 | N6: =IF($A6="","",SUMIFS(المبيعات!$G$5:$G$1004,المبيعات!$D$5:$D$1004,$A6)) -> 0 | O6: =IF($A6="","",SUMIFS('حركة المخزون'!$E$5:$E$1004,'حركة المخزون'!$C$5:$C$1004,$A6,'حركة المخزون'!$B$5:$B$1004,"تالف")+SUMIFS('حركة المخزون'!$E$5:$E$1004,'حركة المخزون'!$C$5:$C$1004,$A6,'حركة المخزون'!$B$5:$B$1004,"عينة / هدية")+SUMIFS('حركة المخزون'!$E$5:$E$1004,'حركة المخزون'!$C$5:$C$1004,$A6,'حركة المخزون'!$B$5:$B$1004,"تسوية نقص")-SUMIFS('حركة المخزون'!$E$5:$E$1004,'حركة المخزون'!$C$5:$C$1004,$A6,'حركة المخزون'!$B$5:$B$1004,"تسوية زيادة")) -> 0 | P6: =IF($A6="","",N(L6)+M6-N6-O6) -> 0 | R6: =IF($A6="","",IF(AND(L6="",M6=0,N6=0),"لم يُسجل رصيد",IF(P6<=0,"نفد",IF(P6<=N(Q6),"أعد الإنتاج","متوفر")))) -> لم يُسجل رصيد | S6: =IF($A6="","",SUMIFS(المبيعات!$J$5:$J$1004,المبيعات!$D$5:$D$1004,$A6)) -> 0 | T6: إنتاج التشغيلة تقديري (10 كجم ÷ 100 جرام). عدّله بعد أول تشغيلة فعلية.
A7: MA-03 | B7: معمول | C7: معمول العرايسي | D7: 80 | E7: جرام | F7: 120 | H7: =IF($A7="","",SUMIFS(الوصفات!$J$5:$J$304,الوصفات!$A$5:$A$304,$A7)) -> 0 | I7: =IF($A7="","",F7-H7) -> 120 | J7: =IF($A7="","",IFERROR(I7/F7,0)) -> 1 | K7: =IF($A7="","",IFERROR(F7/(D7*IF(E7="تولة",الإعدادات!$C$5,1)),0)) -> 1.5 | M7: =IF($A7="","",SUMIFS(الإنتاج!$G$5:$G$504,الإنتاج!$C$5:$C$504,$A7)) -> 0 | N7: =IF($A7="","",SUMIFS(المبيعات!$G$5:$G$1004,المبيعات!$D$5:$D$1004,$A7)) -> 0 | O7: =IF($A7="","",SUMIFS('حركة المخزون'!$E$5:$E$1004,'حركة المخزون'!$C$5:$C$1004,$A7,'حركة المخزون'!$B$5:$B$1004,"تالف")+SUMIFS('حركة المخزون'!$E$5:$E$1004,'حركة المخزون'!$C$5:$C$1004,$A7,'حركة المخزون'!$B$5:$B$1004,"عينة / هدية")+SUMIFS('حركة المخزون'!$E$5:$E$1004,'حركة المخزون'!$C$5:$C$1004,$A7,'حركة المخزون'!$B$5:$B$1004,"تسوية نقص")-SUMIFS('حركة المخزون'!$E$5:$E$1004,'حركة المخزون'!$C$5:$C$1004,$A7,'حركة المخزون'!$B$5:$B$1004,"تسوية زيادة")) -> 0 | P7: =IF($A7="","",N(L7)+M7-N7-O7) -> 0 | R7: =IF($A7="","",IF(AND(L7="",M7=0,N7=0),"لم يُسجل رصيد",IF(P7<=0,"نفد",IF(P7<=N(Q7),"أعد الإنتاج","متوفر")))) -> لم يُسجل رصيد | S7: =IF($A7="","",SUMIFS(المبيعات!$J$5:$J$1004,المبيعات!$D$5:$D$1004,$A7)) -> 0
A8: OU-01 | B8: عود | C8: عود مسقى | D8: 80 | E8: جرام | F8: 95 | H8: =IF($A8="","",SUMIFS(الوصفات!$J$5:$J$304,الوصفات!$A$5:$A$304,$A8)) -> 0 | I8: =IF($A8="","",F8-H8) -> 95 | J8: =IF($A8="","",IFERROR(I8/F8,0)) -> 1 | K8: =IF($A8="","",IFERROR(F8/(D8*IF(E8="تولة",الإعدادات!$C$5,1)),0)) -> 1.1875 | M8: =IF($A8="","",SUMIFS(الإنتاج!$G$5:$G$504,الإنتاج!$C$5:$C$504,$A8)) -> 0 | N8: =IF($A8="","",SUMIFS(المبيعات!$G$5:$G$1004,المبيعات!$D$5:$D$1004,$A8)) -> 0 | O8: =IF($A8="","",SUMIFS('حركة المخزون'!$E$5:$E$1004,'حركة المخزون'!$C$5:$C$1004,$A8,'حركة المخزون'!$B$5:$B$1004,"تالف")+SUMIFS('حركة المخزون'!$E$5:$E$1004,'حركة المخزون'!$C$5:$C$1004,$A8,'حركة المخزون'!$B$5:$B$1004,"عينة / هدية")+SUMIFS('حركة المخزون'!$E$5:$E$1004,'حركة المخزون'!$C$5:$C$1004,$A8,'حركة المخزون'!$B$5:$B$1004,"تسوية نقص")-SUMIFS('حركة المخزون'!$E$5:$E$1004,'حركة المخزون'!$C$5:$C$1004,$A8,'حركة المخزون'!$B$5:$B$1004,"تسوية زيادة")) -> 0 | P8: =IF($A8="","",N(L8)+M8-N8-O8) -> 0 | R8: =IF($A8="","",IF(AND(L8="",M8=0,N8=0),"لم يُسجل رصيد",IF(P8<=0,"نفد",IF(P8<=N(Q8),"أعد الإنتاج","متوفر")))) -> لم يُسجل رصيد | S8: =IF($A8="","",SUMIFS(المبيعات!$J$5:$J$1004,المبيعات!$D$5:$D$1004,$A8)) -> 0
A9: OU-02 | B9: عود | C9: عود طبيعي مسقى زيوت | D9: 80 | E9: جرام | F9: 250 | H9: =IF($A9="","",SUMIFS(الوصفات!$J$5:$J$304,الوصفات!$A$5:$A$304,$A9)) -> 0 | I9: =IF($A9="","",F9-H9) -> 250 | J9: =IF($A9="","",IFERROR(I9/F9,0)) -> 1 | K9: =IF($A9="","",IFERROR(F9/(D9*IF(E9="تولة",الإعدادات!$C$5,1)),0)) -> 3.125 | M9: =IF($A9="","",SUMIFS(الإنتاج!$G$5:$G$504,الإنتاج!$C$5:$C$504,$A9)) -> 0 | N9: =IF($A9="","",SUMIFS(المبيعات!$G$5:$G$1004,المبيعات!$D$5:$D$1004,$A9)) -> 0 | O9: =IF($A9="","",SUMIFS('حركة المخزون'!$E$5:$E$1004,'حركة المخزون'!$C$5:$C$1004,$A9,'حركة المخزون'!$B$5:$B$1004,"تالف")+SUMIFS('حركة المخزون'!$E$5:$E$1004,'حركة المخزون'!$C$5:$C$1004,$A9,'حركة المخزون'!$B$5:$B$1004,"عينة / هدية")+SUMIFS('حركة المخزون'!$E$5:$E$1004,'حركة المخزون'!$C$5:$C$1004,$A9,'حركة المخزون'!$B$5:$B$1004,"تسوية نقص")-SUMIFS('حركة المخزون'!$E$5:$E$1004,'حركة المخزون'!$C$5:$C$1004,$A9,'حركة المخزون'!$B$5:$B$1004,"تسوية زيادة")) -> 0 | P9: =IF($A9="","",N(L9)+M9-N9-O9) -> 0 | R9: =IF($A9="","",IF(AND(L9="",M9=0,N9=0),"لم يُسجل رصيد",IF(P9<=0,"نفد",IF(P9<=N(Q9),"أعد الإنتاج","متوفر")))) -> لم يُسجل رصيد | S9: =IF($A9="","",SUMIFS(المبيعات!$J$5:$J$1004,المبيعات!$D$5:$D$1004,$A9)) -> 0
A10: SP-01 | B10: مرشات | C10: مرش أسيل | D10: 500 | E10: مل | F10: 80 | H10: =IF($A10="","",SUMIFS(الوصفات!$J$5:$J$304,الوصفات!$A$5:$A$304,$A10)) -> 0 | I10: =IF($A10="","",F10-H10) -> 80 | J10: =IF($A10="","",IFERROR(I10/F10,0)) -> 1 | K10: =IF($A10="","",IFERROR(F10/(D10*IF(E10="تولة",الإعدادات!$C$5,1)),0)) -> 0.16 | M10: =IF($A10="","",SUMIFS(الإنتاج!$G$5:$G$504,الإنتاج!$C$5:$C$504,$A10)) -> 0 | N10: =IF($A10="","",SUMIFS(المبيعات!$G$5:$G$1004,المبيعات!$D$5:$D$1004,$A10)) -> 0 | O10: =IF($A10="","",SUMIFS('حركة المخزون'!$E$5:$E$1004,'حركة المخزون'!$C$5:$C$1004,$A10,'حركة المخزون'!$B$5:$B$1004,"تالف")+SUMIFS('حركة المخزون'!$E$5:$E$1004,'حركة المخزون'!$C$5:$C$1004,$A10,'حركة المخزون'!$B$5:$B$1004,"عينة / هدية")+SUMIFS('حركة المخزون'!$E$5:$E$1004,'حركة المخزون'!$C$5:$C$1004,$A10,'حركة المخزون'!$B$5:$B$1004,"تسوية نقص")-SUMIFS('حركة المخزون'!$E$5:$E$1004,'حركة المخزون'!$C$5:$C$1004,$A10,'حركة المخزون'!$B$5:$B$1004,"تسوية زيادة")) -> 0 | P10: =IF($A10="","",N(L10)+M10-N10-O10) -> 0 | R10: =IF($A10="","",IF(AND(L10="",M10=0,N10=0),"لم يُسجل رصيد",IF(P10<=0,"نفد",IF(P10<=N(Q10),"أعد الإنتاج","متوفر")))) -> لم يُسجل رصيد | S10: =IF($A10="","",SUMIFS(المبيعات!$J$5:$J$1004,المبيعات!$D$5:$D$1004,$A10)) -> 0
A11: SP-02 | B11: مرشات | C11: مرش شهد | D11: 500 | E11: مل | F11: 80 | H11: =IF($A11="","",SUMIFS(الوصفات!$J$5:$J$304,الوصفات!$A$5:$A$304,$A11)) -> 0 | I11: =IF($A11="","",F11-H11) -> 80 | J11: =IF($A11="","",IFERROR(I11/F11,0)) -> 1 | K11: =IF($A11="","",IFERROR(F11/(D11*IF(E11="تولة",الإعدادات!$C$5,1)),0)) -> 0.16 | M11: =IF($A11="","",SUMIFS(الإنتاج!$G$5:$G$504,الإنتاج!$C$5:$C$504,$A11)) -> 0 | N11: =IF($A11="","",SUMIFS(المبيعات!$G$5:$G$1004,المبيعات!$D$5:$D$1004,$A11)) -> 0 | O11: =IF($A11="","",SUMIFS('حركة المخزون'!$E$5:$E$1004,'حركة المخزون'!$C$5:$C$1004,$A11,'حركة المخزون'!$B$5:$B$1004,"تالف")+SUMIFS('حركة المخزون'!$E$5:$E$1004,'حركة المخزون'!$C$5:$C$1004,$A11,'حركة المخزون'!$B$5:$B$1004,"عينة / هدية")+SUMIFS('حركة المخزون'!$E$5:$E$1004,'حركة المخزون'!$C$5:$C$1004,$A11,'حركة المخزون'!$B$5:$B$1004,"تسوية نقص")-SUMIFS('حركة المخزون'!$E$5:$E$1004,'حركة المخزون'!$C$5:$C$1004,$A11,'حركة المخزون'!$B$5:$B$1004,"تسوية زيادة")) -> 0 | P11: =IF($A11="","",N(L11)+M11-N11-O11) -> 0 | R11: =IF($A11="","",IF(AND(L11="",M11=0,N11=0),"لم يُسجل رصيد",IF(P11<=0,"نفد",IF(P11<=N(Q11),"أعد الإنتاج","متوفر")))) -> لم يُسجل رصيد | S11: =IF($A11="","",SUMIFS(المبيعات!$J$5:$J$1004,المبيعات!$D$5:$D$1004,$A11)) -> 0
A12: SP-03 | B12: مرشات | C12: مرش سديم | D12: 500 | E12: مل | F12: 80 | H12: =IF($A12="","",SUMIFS(الوصفات!$J$5:$J$304,الوصفات!$A$5:$A$304,$A12)) -> 0 | I12: =IF($A12="","",F12-H12) -> 80 | J12: =IF($A12="","",IFERROR(I12/F12,0)) -> 1 | K12: =IF($A12="","",IFERROR(F12/(D12*IF(E12="تولة",الإعدادات!$C$5,1)),0)) -> 0.16 | M12: =IF($A12="","",SUMIFS(الإنتاج!$G$5:$G$504,الإنتاج!$C$5:$C$504,$A12)) -> 0 | N12: =IF($A12="","",SUMIFS(المبيعات!$G$5:$G$1004,المبيعات!$D$5:$D$1004,$A12)) -> 0 | O12: =IF($A12="","",SUMIFS('حركة المخزون'!$E$5:$E$1004,'حركة المخزون'!$C$5:$C$1004,$A12,'حركة المخزون'!$B$5:$B$1004,"تالف")+SUMIFS('حركة المخزون'!$E$5:$E$1004,'حركة المخزون'!$C$5:$C$1004,$A12,'حركة المخزون'!$B$5:$B$1004,"عينة / هدية")+SUMIFS('حركة المخزون'!$E$5:$E$1004,'حركة المخزون'!$C$5:$C$1004,$A12,'حركة المخزون'!$B$5:$B$1004,"تسوية نقص")-SUMIFS('حركة المخزون'!$E$5:$E$1004,'حركة المخزون'!$C$5:$C$1004,$A12,'حركة المخزون'!$B$5:$B$1004,"تسوية زيادة")) -> 0 | P12: =IF($A12="","",N(L12)+M12-N12-O12) -> 0 | R12: =IF($A12="","",IF(AND(L12="",M12=0,N12=0),"لم يُسجل رصيد",IF(P12<=0,"نفد",IF(P12<=N(Q12),"أعد الإنتاج","متوفر")))) -> لم يُسجل رصيد | S12: =IF($A12="","",SUMIFS(المبيعات!$J$5:$J$1004,المبيعات!$D$5:$D$1004,$A12)) -> 0
A13: OI-01 | B13: أدهان | C13: فتشة العروس | D13: 1 | E13: تولة | F13: 70 | H13: =IF($A13="","",SUMIFS(الوصفات!$J$5:$J$304,الوصفات!$A$5:$A$304,$A13)) -> 0 | I13: =IF($A13="","",F13-H13) -> 70 | J13: =IF($A13="","",IFERROR(I13/F13,0)) -> 1 | K13: =IF($A13="","",IFERROR(F13/(D13*IF(E13="تولة",الإعدادات!$C$5,1)),0)) -> 6.0034305 | M13: =IF($A13="","",SUMIFS(الإنتاج!$G$5:$G$504,الإنتاج!$C$5:$C$504,$A13)) -> 0 | N13: =IF($A13="","",SUMIFS(المبيعات!$G$5:$G$1004,المبيعات!$D$5:$D$1004,$A13)) -> 0 | O13: =IF($A13="","",SUMIFS('حركة المخزون'!$E$5:$E$1004,'حركة المخزون'!$C$5:$C$1004,$A13,'حركة المخزون'!$B$5:$B$1004,"تالف")+SUMIFS('حركة المخزون'!$E$5:$E$1004,'حركة المخزون'!$C$5:$C$1004,$A13,'حركة المخزون'!$B$5:$B$1004,"عينة / هدية")+SUMIFS('حركة المخزون'!$E$5:$E$1004,'حركة المخزون'!$C$5:$C$1004,$A13,'حركة المخزون'!$B$5:$B$1004,"تسوية نقص")-SUMIFS('حركة المخزون'!$E$5:$E$1004,'حركة المخزون'!$C$5:$C$1004,$A13,'حركة المخزون'!$B$5:$B$1004,"تسوية زيادة")) -> 0 | P13: =IF($A13="","",N(L13)+M13-N13-O13) -> 0 | R13: =IF($A13="","",IF(AND(L13="",M13=0,N13=0),"لم يُسجل رصيد",IF(P13<=0,"نفد",IF(P13<=N(Q13),"أعد الإنتاج","متوفر")))) -> لم يُسجل رصيد | S13: =IF($A13="","",SUMIFS(المبيعات!$J$5:$J$1004,المبيعات!$D$5:$D$1004,$A13)) -> 0
A14: OI-02 | B14: أدهان | C14: خمرية الزعفران | D14: 1 | E14: تولة | F14: 60 | H14: =IF($A14="","",SUMIFS(الوصفات!$J$5:$J$304,الوصفات!$A$5:$A$304,$A14)) -> 0 | I14: =IF($A14="","",F14-H14) -> 60 | J14: =IF($A14="","",IFERROR(I14/F14,0)) -> 1 | K14: =IF($A14="","",IFERROR(F14/(D14*IF(E14="تولة",الإعدادات!$C$5,1)),0)) -> 5.1457976 | M14: =IF($A14="","",SUMIFS(الإنتاج!$G$5:$G$504,الإنتاج!$C$5:$C$504,$A14)) -> 0 | N14: =IF($A14="","",SUMIFS(المبيعات!$G$5:$G$1004,المبيعات!$D$5:$D$1004,$A14)) -> 0 | O14: =IF($A14="","",SUMIFS('حركة المخزون'!$E$5:$E$1004,'حركة المخزون'!$C$5:$C$1004,$A14,'حركة المخزون'!$B$5:$B$1004,"تالف")+SUMIFS('حركة المخزون'!$E$5:$E$1004,'حركة المخزون'!$C$5:$C$1004,$A14,'حركة المخزون'!$B$5:$B$1004,"عينة / هدية")+SUMIFS('حركة المخزون'!$E$5:$E$1004,'حركة المخزون'!$C$5:$C$1004,$A14,'حركة المخزون'!$B$5:$B$1004,"تسوية نقص")-SUMIFS('حركة المخزون'!$E$5:$E$1004,'حركة المخزون'!$C$5:$C$1004,$A14,'حركة المخزون'!$B$5:$B$1004,"تسوية زيادة")) -> 0 | P14: =IF($A14="","",N(L14)+M14-N14-O14) -> 0 | R14: =IF($A14="","",IF(AND(L14="",M14=0,N14=0),"لم يُسجل رصيد",IF(P14<=0,"نفد",IF(P14<=N(Q14),"أعد الإنتاج","متوفر")))) -> لم يُسجل رصيد | S14: =IF($A14="","",SUMIFS(المبيعات!$J$5:$J$1004,المبيعات!$D$5:$D$1004,$A14)) -> 0
A15: OI-03 | B15: أدهان | C15: خمرية المسك | D15: 1 | E15: تولة | F15: 60 | H15: =IF($A15="","",SUMIFS(الوصفات!$J$5:$J$304,الوصفات!$A$5:$A$304,$A15)) -> 0 | I15: =IF($A15="","",F15-H15) -> 60 | J15: =IF($A15="","",IFERROR(I15/F15,0)) -> 1 | K15: =IF($A15="","",IFERROR(F15/(D15*IF(E15="تولة",الإعدادات!$C$5,1)),0)) -> 5.1457976 | M15: =IF($A15="","",SUMIFS(الإنتاج!$G$5:$G$504,الإنتاج!$C$5:$C$504,$A15)) -> 0 | N15: =IF($A15="","",SUMIFS(المبيعات!$G$5:$G$1004,المبيعات!$D$5:$D$1004,$A15)) -> 0 | O15: =IF($A15="","",SUMIFS('حركة المخزون'!$E$5:$E$1004,'حركة المخزون'!$C$5:$C$1004,$A15,'حركة المخزون'!$B$5:$B$1004,"تالف")+SUMIFS('حركة المخزون'!$E$5:$E$1004,'حركة المخزون'!$C$5:$C$1004,$A15,'حركة المخزون'!$B$5:$B$1004,"عينة / هدية")+SUMIFS('حركة المخزون'!$E$5:$E$1004,'حركة المخزون'!$C$5:$C$1004,$A15,'حركة المخزون'!$B$5:$B$1004,"تسوية نقص")-SUMIFS('حركة المخزون'!$E$5:$E$1004,'حركة المخزون'!$C$5:$C$1004,$A15,'حركة المخزون'!$B$5:$B$1004,"تسوية زيادة")) -> 0 | P15: =IF($A15="","",N(L15)+M15-N15-O15) -> 0 | R15: =IF($A15="","",IF(AND(L15="",M15=0,N15=0),"لم يُسجل رصيد",IF(P15<=0,"نفد",IF(P15<=N(Q15),"أعد الإنتاج","متوفر")))) -> لم يُسجل رصيد | S15: =IF($A15="","",SUMIFS(المبيعات!$J$5:$J$1004,المبيعات!$D$5:$D$1004,$A15)) -> 0
A16: OI-04 | B16: أدهان | C16: دهن العود الطبيعي | D16: 0.25 | E16: تولة | F16: 120 | H16: =IF($A16="","",SUMIFS(الوصفات!$J$5:$J$304,الوصفات!$A$5:$A$304,$A16)) -> 0 | I16: =IF($A16="","",F16-H16) -> 120 | J16: =IF($A16="","",IFERROR(I16/F16,0)) -> 1 | K16: =IF($A16="","",IFERROR(F16/(D16*IF(E16="تولة",الإعدادات!$C$5,1)),0)) -> 41.166381 | M16: =IF($A16="","",SUMIFS(الإنتاج!$G$5:$G$504,الإنتاج!$C$5:$C$504,$A16)) -> 0 | N16: =IF($A16="","",SUMIFS(المبيعات!$G$5:$G$1004,المبيعات!$D$5:$D$1004,$A16)) -> 0 | O16: =IF($A16="","",SUMIFS('حركة المخزون'!$E$5:$E$1004,'حركة المخزون'!$C$5:$C$1004,$A16,'حركة المخزون'!$B$5:$B$1004,"تالف")+SUMIFS('حركة المخزون'!$E$5:$E$1004,'حركة المخزون'!$C$5:$C$1004,$A16,'حركة المخزون'!$B$5:$B$1004,"عينة / هدية")+SUMIFS('حركة المخزون'!$E$5:$E$1004,'حركة المخزون'!$C$5:$C$1004,$A16,'حركة المخزون'!$B$5:$B$1004,"تسوية نقص")-SUMIFS('حركة المخزون'!$E$5:$E$1004,'حركة المخزون'!$C$5:$C$1004,$A16,'حركة المخزون'!$B$5:$B$1004,"تسوية زيادة")) -> 0 | P16: =IF($A16="","",N(L16)+M16-N16-O16) -> 0 | R16: =IF($A16="","",IF(AND(L16="",M16=0,N16=0),"لم يُسجل رصيد",IF(P16<=0,"نفد",IF(P16<=N(Q16),"أعد الإنتاج","متوفر")))) -> لم يُسجل رصيد | S16: =IF($A16="","",SUMIFS(المبيعات!$J$5:$J$1004,المبيعات!$D$5:$D$1004,$A16)) -> 0
H17: =IF($A17="","",SUMIFS(الوصفات!$J$5:$J$304,الوصفات!$A$5:$A$304,$A17)) | I17: =IF($A17="","",F17-H17) | J17: =IF($A17="","",IFERROR(I17/F17,0)) | K17: =IF($A17="","",IFERROR(F17/(D17*IF(E17="تولة",الإعدادات!$C$5,1)),0)) | M17: =IF($A17="","",SUMIFS(الإنتاج!$G$5:$G$504,الإنتاج!$C$5:$C$504,$A17)) | N17: =IF($A17="","",SUMIFS(المبيعات!$G$5:$G$1004,المبيعات!$D$5:$D$1004,$A17)) | O17: =IF($A17="","",SUMIFS('حركة المخزون'!$E$5:$E$1004,'حركة المخزون'!$C$5:$C$1004,$A17,'حركة المخزون'!$B$5:$B$1004,"تالف")+SUMIFS('حركة المخزون'!$E$5:$E$1004,'حركة المخزون'!$C$5:$C$1004,$A17,'حركة المخزون'!$B$5:$B$1004,"عينة / هدية")+SUMIFS('حركة المخزون'!$E$5:$E$1004,'حركة المخزون'!$C$5:$C$1004,$A17,'حركة المخزون'!$B$5:$B$1004,"تسوية نقص")-SUMIFS('حركة المخزون'!$E$5:$E$1004,'حركة المخزون'!$C$5:$C$1004,$A17,'حركة المخزون'!$B$5:$B$1004,"تسوية زيادة")) | P17: =IF($A17="","",N(L17)+M17-N17-O17) | R17: =IF($A17="","",IF(AND(L17="",M17=0,N17=0),"لم يُسجل رصيد",IF(P17<=0,"نفد",IF(P17<=N(Q17),"أعد الإنتاج","متوفر")))) | S17: =IF($A17="","",SUMIFS(المبيعات!$J$5:$J$1004,المبيعات!$D$5:$D$1004,$A17))
H18: =IF($A18="","",SUMIFS(الوصفات!$J$5:$J$304,الوصفات!$A$5:$A$304,$A18)) | I18: =IF($A18="","",F18-H18) | J18: =IF($A18="","",IFERROR(I18/F18,0)) | K18: =IF($A18="","",IFERROR(F18/(D18*IF(E18="تولة",الإعدادات!$C$5,1)),0)) | M18: =IF($A18="","",SUMIFS(الإنتاج!$G$5:$G$504,الإنتاج!$C$5:$C$504,$A18)) | N18: =IF($A18="","",SUMIFS(المبيعات!$G$5:$G$1004,المبيعات!$D$5:$D$1004,$A18)) | O18: =IF($A18="","",SUMIFS('حركة المخزون'!$E$5:$E$1004,'حركة المخزون'!$C$5:$C$1004,$A18,'حركة المخزون'!$B$5:$B$1004,"تالف")+SUMIFS('حركة المخزون'!$E$5:$E$1004,'حركة المخزون'!$C$5:$C$1004,$A18,'حركة المخزون'!$B$5:$B$1004,"عينة / هدية")+SUMIFS('حركة المخزون'!$E$5:$E$1004,'حركة المخزون'!$C$5:$C$1004,$A18,'حركة المخزون'!$B$5:$B$1004,"تسوية نقص")-SUMIFS('حركة المخزون'!$E$5:$E$1004,'حركة المخزون'!$C$5:$C$1004,$A18,'حركة المخزون'!$B$5:$B$1004,"تسوية زيادة")) | P18: =IF($A18="","",N(L18)+M18-N18-O18) | R18: =IF($A18="","",IF(AND(L18="",M18=0,N18=0),"لم يُسجل رصيد",IF(P18<=0,"نفد",IF(P18<=N(Q18),"أعد الإنتاج","متوفر")))) | S18: =IF($A18="","",SUMIFS(المبيعات!$J$5:$J$1004,المبيعات!$D$5:$D$1004,$A18))
H19: =IF($A19="","",SUMIFS(الوصفات!$J$5:$J$304,الوصفات!$A$5:$A$304,$A19)) | I19: =IF($A19="","",F19-H19) | J19: =IF($A19="","",IFERROR(I19/F19,0)) | K19: =IF($A19="","",IFERROR(F19/(D19*IF(E19="تولة",الإعدادات!$C$5,1)),0)) | M19: =IF($A19="","",SUMIFS(الإنتاج!$G$5:$G$504,الإنتاج!$C$5:$C$504,$A19)) | N19: =IF($A19="","",SUMIFS(المبيعات!$G$5:$G$1004,المبيعات!$D$5:$D$1004,$A19)) | O19: =IF($A19="","",SUMIFS('حركة المخزون'!$E$5:$E$1004,'حركة المخزون'!$C$5:$C$1004,$A19,'حركة المخزون'!$B$5:$B$1004,"تالف")+SUMIFS('حركة المخزون'!$E$5:$E$1004,'حركة المخزون'!$C$5:$C$1004,$A19,'حركة المخزون'!$B$5:$B$1004,"عينة / هدية")+SUMIFS('حركة المخزون'!$E$5:$E$1004,'حركة المخزون'!$C$5:$C$1004,$A19,'حركة المخزون'!$B$5:$B$1004,"تسوية نقص")-SUMIFS('حركة المخزون'!$E$5:$E$1004,'حركة المخزون'!$C$5:$C$1004,$A19,'حركة المخزون'!$B$5:$B$1004,"تسوية زيادة")) | P19: =IF($A19="","",N(L19)+M19-N19-O19) | R19: =IF($A19="","",IF(AND(L19="",M19=0,N19=0),"لم يُسجل رصيد",IF(P19<=0,"نفد",IF(P19<=N(Q19),"أعد الإنتاج","متوفر")))) | S19: =IF($A19="","",SUMIFS(المبيعات!$J$5:$J$1004,المبيعات!$D$5:$D$1004,$A19))
H20: =IF($A20="","",SUMIFS(الوصفات!$J$5:$J$304,الوصفات!$A$5:$A$304,$A20)) | I20: =IF($A20="","",F20-H20) | J20: =IF($A20="","",IFERROR(I20/F20,0)) | K20: =IF($A20="","",IFERROR(F20/(D20*IF(E20="تولة",الإعدادات!$C$5,1)),0)) | M20: =IF($A20="","",SUMIFS(الإنتاج!$G$5:$G$504,الإنتاج!$C$5:$C$504,$A20)) | N20: =IF($A20="","",SUMIFS(المبيعات!$G$5:$G$1004,المبيعات!$D$5:$D$1004,$A20)) | O20: =IF($A20="","",SUMIFS('حركة المخزون'!$E$5:$E$1004,'حركة المخزون'!$C$5:$C$1004,$A20,'حركة المخزون'!$B$5:$B$1004,"تالف")+SUMIFS('حركة المخزون'!$E$5:$E$1004,'حركة المخزون'!$C$5:$C$1004,$A20,'حركة المخزون'!$B$5:$B$1004,"عينة / هدية")+SUMIFS('حركة المخزون'!$E$5:$E$1004,'حركة المخزون'!$C$5:$C$1004,$A20,'حركة المخزون'!$B$5:$B$1004,"تسوية نقص")-SUMIFS('حركة المخزون'!$E$5:$E$1004,'حركة المخزون'!$C$5:$C$1004,$A20,'حركة المخزون'!$B$5:$B$1004,"تسوية زيادة")) | P20: =IF($A20="","",N(L20)+M20-N20-O20) | R20: =IF($A20="","",IF(AND(L20="",M20=0,N20=0),"لم يُسجل رصيد",IF(P20<=0,"نفد",IF(P20<=N(Q20),"أعد الإنتاج","متوفر")))) | S20: =IF($A20="","",SUMIFS(المبيعات!$J$5:$J$1004,المبيعات!$D$5:$D$1004,$A20))
H21: =IF($A21="","",SUMIFS(الوصفات!$J$5:$J$304,الوصفات!$A$5:$A$304,$A21)) | I21: =IF($A21="","",F21-H21) | J21: =IF($A21="","",IFERROR(I21/F21,0)) | K21: =IF($A21="","",IFERROR(F21/(D21*IF(E21="تولة",الإعدادات!$C$5,1)),0)) | M21: =IF($A21="","",SUMIFS(الإنتاج!$G$5:$G$504,الإنتاج!$C$5:$C$504,$A21)) | N21: =IF($A21="","",SUMIFS(المبيعات!$G$5:$G$1004,المبيعات!$D$5:$D$1004,$A21)) | O21: =IF($A21="","",SUMIFS('حركة المخزون'!$E$5:$E$1004,'حركة المخزون'!$C$5:$C$1004,$A21,'حركة المخزون'!$B$5:$B$1004,"تالف")+SUMIFS('حركة المخزون'!$E$5:$E$1004,'حركة المخزون'!$C$5:$C$1004,$A21,'حركة المخزون'!$B$5:$B$1004,"عينة / هدية")+SUMIFS('حركة المخزون'!$E$5:$E$1004,'حركة المخزون'!$C$5:$C$1004,$A21,'حركة المخزون'!$B$5:$B$1004,"تسوية نقص")-SUMIFS('حركة المخزون'!$E$5:$E$1004,'حركة المخزون'!$C$5:$C$1004,$A21,'حركة المخزون'!$B$5:$B$1004,"تسوية زيادة")) | P21: =IF($A21="","",N(L21)+M21-N21-O21) | R21: =IF($A21="","",IF(AND(L21="",M21=0,N21=0),"لم يُسجل رصيد",IF(P21<=0,"نفد",IF(P21<=N(Q21),"أعد الإنتاج","متوفر")))) | S21: =IF($A21="","",SUMIFS(المبيعات!$J$5:$J$1004,المبيعات!$D$5:$D$1004,$A21))
H22: =IF($A22="","",SUMIFS(الوصفات!$J$5:$J$304,الوصفات!$A$5:$A$304,$A22)) | I22: =IF($A22="","",F22-H22) | J22: =IF($A22="","",IFERROR(I22/F22,0)) | K22: =IF($A22="","",IFERROR(F22/(D22*IF(E22="تولة",الإعدادات!$C$5,1)),0)) | M22: =IF($A22="","",SUMIFS(الإنتاج!$G$5:$G$504,الإنتاج!$C$5:$C$504,$A22)) | N22: =IF($A22="","",SUMIFS(المبيعات!$G$5:$G$1004,المبيعات!$D$5:$D$1004,$A22)) | O22: =IF($A22="","",SUMIFS('حركة المخزون'!$E$5:$E$1004,'حركة المخزون'!$C$5:$C$1004,$A22,'حركة المخزون'!$B$5:$B$1004,"تالف")+SUMIFS('حركة المخزون'!$E$5:$E$1004,'حركة المخزون'!$C$5:$C$1004,$A22,'حركة المخزون'!$B$5:$B$1004,"عينة / هدية")+SUMIFS('حركة المخزون'!$E$5:$E$1004,'حركة المخزون'!$C$5:$C$1004,$A22,'حركة المخزون'!$B$5:$B$1004,"تسوية نقص")-SUMIFS('حركة المخزون'!$E$5:$E$1004,'حركة المخزون'!$C$5:$C$1004,$A22,'حركة المخزون'!$B$5:$B$1004,"تسوية زيادة")) | P22: =IF($A22="","",N(L22)+M22-N22-O22) | R22: =IF($A22="","",IF(AND(L22="",M22=0,N22=0),"لم يُسجل رصيد",IF(P22<=0,"نفد",IF(P22<=N(Q22),"أعد الإنتاج","متوفر")))) | S22: =IF($A22="","",SUMIFS(المبيعات!$J$5:$J$1004,المبيعات!$D$5:$D$1004,$A22))
H23: =IF($A23="","",SUMIFS(الوصفات!$J$5:$J$304,الوصفات!$A$5:$A$304,$A23)) | I23: =IF($A23="","",F23-H23) | J23: =IF($A23="","",IFERROR(I23/F23,0)) | K23: =IF($A23="","",IFERROR(F23/(D23*IF(E23="تولة",الإعدادات!$C$5,1)),0)) | M23: =IF($A23="","",SUMIFS(الإنتاج!$G$5:$G$504,الإنتاج!$C$5:$C$504,$A23)) | N23: =IF($A23="","",SUMIFS(المبيعات!$G$5:$G$1004,المبيعات!$D$5:$D$1004,$A23)) | O23: =IF($A23="","",SUMIFS('حركة المخزون'!$E$5:$E$1004,'حركة المخزون'!$C$5:$C$1004,$A23,'حركة المخزون'!$B$5:$B$1004,"تالف")+SUMIFS('حركة المخزون'!$E$5:$E$1004,'حركة المخزون'!$C$5:$C$1004,$A23,'حركة المخزون'!$B$5:$B$1004,"عينة / هدية")+SUMIFS('حركة المخزون'!$E$5:$E$1004,'حركة المخزون'!$C$5:$C$1004,$A23,'حركة المخزون'!$B$5:$B$1004,"تسوية نقص")-SUMIFS('حركة المخزون'!$E$5:$E$1004,'حركة المخزون'!$C$5:$C$1004,$A23,'حركة المخزون'!$B$5:$B$1004,"تسوية زيادة")) | P23: =IF($A23="","",N(L23)+M23-N23-O23) | R23: =IF($A23="","",IF(AND(L23="",M23=0,N23=0),"لم يُسجل رصيد",IF(P23<=0,"نفد",IF(P23<=N(Q23),"أعد الإنتاج","متوفر")))) | S23: =IF($A23="","",SUMIFS(المبيعات!$J$5:$J$1004,المبيعات!$D$5:$D$1004,$A23))
H24: =IF($A24="","",SUMIFS(الوصفات!$J$5:$J$304,الوصفات!$A$5:$A$304,$A24)) | I24: =IF($A24="","",F24-H24) | J24: =IF($A24="","",IFERROR(I24/F24,0)) | K24: =IF($A24="","",IFERROR(F24/(D24*IF(E24="تولة",الإعدادات!$C$5,1)),0)) | M24: =IF($A24="","",SUMIFS(الإنتاج!$G$5:$G$504,الإنتاج!$C$5:$C$504,$A24)) | N24: =IF($A24="","",SUMIFS(المبيعات!$G$5:$G$1004,المبيعات!$D$5:$D$1004,$A24)) | O24: =IF($A24="","",SUMIFS('حركة المخزون'!$E$5:$E$1004,'حركة المخزون'!$C$5:$C$1004,$A24,'حركة المخزون'!$B$5:$B$1004,"تالف")+SUMIFS('حركة المخزون'!$E$5:$E$1004,'حركة المخزون'!$C$5:$C$1004,$A24,'حركة المخزون'!$B$5:$B$1004,"عينة / هدية")+SUMIFS('حركة المخزون'!$E$5:$E$1004,'حركة المخزون'!$C$5:$C$1004,$A24,'حركة المخزون'!$B$5:$B$1004,"تسوية نقص")-SUMIFS('حركة المخزون'!$E$5:$E$1004,'حركة المخزون'!$C$5:$C$1004,$A24,'حركة المخزون'!$B$5:$B$1004,"تسوية زيادة")) | P24: =IF($A24="","",N(L24)+M24-N24-O24) | R24: =IF($A24="","",IF(AND(L24="",M24=0,N24=0),"لم يُسجل رصيد",IF(P24<=0,"نفد",IF(P24<=N(Q24),"أعد الإنتاج","متوفر")))) | S24: =IF($A24="","",SUMIFS(المبيعات!$J$5:$J$1004,المبيعات!$D$5:$D$1004,$A24))

Sheet الوصفات
A1: الوصفات (التركيبة الثابتة لكل منتج)
A2: كل سطر = مادة وحدة داخل منتج. «لكل تشغيلة» للمواد اللي تنخلط مرة وحدة (مثل 10 كجم بودرة + 30 جرام زيت)، و«لكل حبة» للتغليف (علبة، ملصق). لما تسجل تشغيلة في صفحة الإنتاج تنخصم الكميات من المواد الخام تلقائياً.
A4: كود المنتج | B4: اسم المنتج | C4: كود المادة | D4: اسم المادة | E4: الأساس | F4: الكمية | G4: الوحدة | H4: تكلفة الوحدة | I4: تكلفة السطر | J4: التكلفة على الحبة | K4: المستهلك الكلي (من الإنتاج) | L4: ملاحظات
A5: MA-02 | B5: =IF($A5="","",IFERROR(INDEX(المنتجات!$C$5:$C$24,MATCH($A5,المنتجات!$A$5:$A$24,0)),"كود غير موجود")) -> معمول المخصوص (الدوسري) | C5: RM-001 | D5: =IF($C5="","",IFERROR(INDEX('المواد الخام'!$B$5:$B$104,MATCH($C5,'المواد الخام'!$A$5:$A$104,0)),"كود غير موجود")) -> بودرة عود | E5: لكل تشغيلة | F5: 10000 | G5: =IF($C5="","",IFERROR(INDEX('المواد الخام'!$D$5:$D$104,MATCH($C5,'المواد الخام'!$A$5:$A$104,0)),"")) -> جرام | H5: =IF($C5="","",IFERROR(INDEX('المواد الخام'!$G$5:$G$104,MATCH($C5,'المواد الخام'!$A$5:$A$104,0)),0)) -> 0 | I5: =IF($C5="","",N(F5)*N(H5)) -> 0 | J5: =IF(OR($A5="",$C5=""),"",IF(E5="لكل حبة",I5,IFERROR(I5/INDEX(المنتجات!$G$5:$G$24,MATCH($A5,المنتجات!$A$5:$A$24,0)),0))) -> 0 | K5: =IF(OR($A5="",$C5=""),"",N(F5)*IF(E5="لكل حبة",SUMIFS(الإنتاج!$G$5:$G$504,الإنتاج!$C$5:$C$504,$A5),SUMIFS(الإنتاج!$E$5:$E$504,الإنتاج!$C$5:$C$504,$A5))) -> 0 | L5: من صاحب المشروع: 10 كجم بودرة عود
A6: MA-02 | B6: =IF($A6="","",IFERROR(INDEX(المنتجات!$C$5:$C$24,MATCH($A6,المنتجات!$A$5:$A$24,0)),"كود غير موجود")) -> معمول المخصوص (الدوسري) | C6: RM-002 | D6: =IF($C6="","",IFERROR(INDEX('المواد الخام'!$B$5:$B$104,MATCH($C6,'المواد الخام'!$A$5:$A$104,0)),"كود غير موجود")) -> زيت عطري (خلطة المعمول) | E6: لكل تشغيلة | F6: 30 | G6: =IF($C6="","",IFERROR(INDEX('المواد الخام'!$D$5:$D$104,MATCH($C6,'المواد الخام'!$A$5:$A$104,0)),"")) -> جرام | H6: =IF($C6="","",IFERROR(INDEX('المواد الخام'!$G$5:$G$104,MATCH($C6,'المواد الخام'!$A$5:$A$104,0)),0)) -> 0 | I6: =IF($C6="","",N(F6)*N(H6)) -> 0 | J6: =IF(OR($A6="",$C6=""),"",IF(E6="لكل حبة",I6,IFERROR(I6/INDEX(المنتجات!$G$5:$G$24,MATCH($A6,المنتجات!$A$5:$A$24,0)),0))) -> 0 | K6: =IF(OR($A6="",$C6=""),"",N(F6)*IF(E6="لكل حبة",SUMIFS(الإنتاج!$G$5:$G$504,الإنتاج!$C$5:$C$504,$A6),SUMIFS(الإنتاج!$E$5:$E$504,الإنتاج!$C$5:$C$504,$A6))) -> 0 | L6: من صاحب المشروع: 30 جرام زيت
A7: MA-02 | B7: =IF($A7="","",IFERROR(INDEX(المنتجات!$C$5:$C$24,MATCH($A7,المنتجات!$A$5:$A$24,0)),"كود غير موجود")) -> معمول المخصوص (الدوسري) | C7: PK-001 | D7: =IF($C7="","",IFERROR(INDEX('المواد الخام'!$B$5:$B$104,MATCH($C7,'المواد الخام'!$A$5:$A$104,0)),"كود غير موجود")) -> علبة معمول (أسود / ذهبي) | E7: لكل حبة | F7: 1 | G7: =IF($C7="","",IFERROR(INDEX('المواد الخام'!$D$5:$D$104,MATCH($C7,'المواد الخام'!$A$5:$A$104,0)),"")) -> حبة | H7: =IF($C7="","",IFERROR(INDEX('المواد الخام'!$G$5:$G$104,MATCH($C7,'المواد الخام'!$A$5:$A$104,0)),0)) -> 0 | I7: =IF($C7="","",N(F7)*N(H7)) -> 0 | J7: =IF(OR($A7="",$C7=""),"",IF(E7="لكل حبة",I7,IFERROR(I7/INDEX(المنتجات!$G$5:$G$24,MATCH($A7,المنتجات!$A$5:$A$24,0)),0))) -> 0 | K7: =IF(OR($A7="",$C7=""),"",N(F7)*IF(E7="لكل حبة",SUMIFS(الإنتاج!$G$5:$G$504,الإنتاج!$C$5:$C$504,$A7),SUMIFS(الإنتاج!$E$5:$E$504,الإنتاج!$C$5:$C$504,$A7))) -> 0 | L7: علبة وحدة لكل حبة
A8: MA-02 | B8: =IF($A8="","",IFERROR(INDEX(المنتجات!$C$5:$C$24,MATCH($A8,المنتجات!$A$5:$A$24,0)),"كود غير موجود")) -> معمول المخصوص (الدوسري) | C8: PK-003 | D8: =IF($C8="","",IFERROR(INDEX('المواد الخام'!$B$5:$B$104,MATCH($C8,'المواد الخام'!$A$5:$A$104,0)),"كود غير موجود")) -> ملصق علبة | E8: لكل حبة | F8: 1 | G8: =IF($C8="","",IFERROR(INDEX('المواد الخام'!$D$5:$D$104,MATCH($C8,'المواد الخام'!$A$5:$A$104,0)),"")) -> حبة | H8: =IF($C8="","",IFERROR(INDEX('المواد الخام'!$G$5:$G$104,MATCH($C8,'المواد الخام'!$A$5:$A$104,0)),0)) -> 0 | I8: =IF($C8="","",N(F8)*N(H8)) -> 0 | J8: =IF(OR($A8="",$C8=""),"",IF(E8="لكل حبة",I8,IFERROR(I8/INDEX(المنتجات!$G$5:$G$24,MATCH($A8,المنتجات!$A$5:$A$24,0)),0))) -> 0 | K8: =IF(OR($A8="",$C8=""),"",N(F8)*IF(E8="لكل حبة",SUMIFS(الإنتاج!$G$5:$G$504,الإنتاج!$C$5:$C$504,$A8),SUMIFS(الإنتاج!$E$5:$E$504,الإنتاج!$C$5:$C$504,$A8))) -> 0 | L8: ملصق واحد لكل حبة
B9: =IF($A9="","",IFERROR(INDEX(المنتجات!$C$5:$C$24,MATCH($A9,المنتجات!$A$5:$A$24,0)),"كود غير موجود")) | D9: =IF($C9="","",IFERROR(INDEX('المواد الخام'!$B$5:$B$104,MATCH($C9,'المواد الخام'!$A$5:$A$104,0)),"كود غير موجود")) | G9: =IF($C9="","",IFERROR(INDEX('المواد الخام'!$D$5:$D$104,MATCH($C9,'المواد الخام'!$A$5:$A$104,0)),"")) | H9: =IF($C9="","",IFERROR(INDEX('المواد الخام'!$G$5:$G$104,MATCH($C9,'المواد الخام'!$A$5:$A$104,0)),0)) | I9: =IF($C9="","",N(F9)*N(H9)) | J9: =IF(OR($A9="",$C9=""),"",IF(E9="لكل حبة",I9,IFERROR(I9/INDEX(المنتجات!$G$5:$G$24,MATCH($A9,المنتجات!$A$5:$A$24,0)),0))) | K9: =IF(OR($A9="",$C9=""),"",N(F9)*IF(E9="لكل حبة",SUMIFS(الإنتاج!$G$5:$G$504,الإنتاج!$C$5:$C$504,$A9),SUMIFS(الإنتاج!$E$5:$E$504,الإنتاج!$C$5:$C$504,$A9)))
B10: =IF($A10="","",IFERROR(INDEX(المنتجات!$C$5:$C$24,MATCH($A10,المنتجات!$A$5:$A$24,0)),"كود غير موجود")) | D10: =IF($C10="","",IFERROR(INDEX('المواد الخام'!$B$5:$B$104,MATCH($C10,'المواد الخام'!$A$5:$A$104,0)),"كود غير موجود")) | G10: =IF($C10="","",IFERROR(INDEX('المواد الخام'!$D$5:$D$104,MATCH($C10,'المواد الخام'!$A$5:$A$104,0)),"")) | H10: =IF($C10="","",IFERROR(INDEX('المواد الخام'!$G$5:$G$104,MATCH($C10,'المواد الخام'!$A$5:$A$104,0)),0)) | I10: =IF($C10="","",N(F10)*N(H10)) | J10: =IF(OR($A10="",$C10=""),"",IF(E10="لكل حبة",I10,IFERROR(I10/INDEX(المنتجات!$G$5:$G$24,MATCH($A10,المنتجات!$A$5:$A$24,0)),0))) | K10: =IF(OR($A10="",$C10=""),"",N(F10)*IF(E10="لكل حبة",SUMIFS(الإنتاج!$G$5:$G$504,الإنتاج!$C$5:$C$504,$A10),SUMIFS(الإنتاج!$E$5:$E$504,الإنتاج!$C$5:$C$504,$A10)))
B11: =IF($A11="","",IFERROR(INDEX(المنتجات!$C$5:$C$24,MATCH($A11,المنتجات!$A$5:$A$24,0)),"كود غير موجود")) | D11: =IF($C11="","",IFERROR(INDEX('المواد الخام'!$B$5:$B$104,MATCH($C11,'المواد الخام'!$A$5:$A$104,0)),"كود غير موجود")) | G11: =IF($C11="","",IFERROR(INDEX('المواد الخام'!$D$5:$D$104,MATCH($C11,'المواد الخام'!$A$5:$A$104,0)),"")) | H11: =IF($C11="","",IFERROR(INDEX('المواد الخام'!$G$5:$G$104,MATCH($C11,'المواد الخام'!$A$5:$A$104,0)),0)) | I11: =IF($C11="","",N(F11)*N(H11)) | J11: =IF(OR($A11="",$C11=""),"",IF(E11="لكل حبة",I11,IFERROR(I11/INDEX(المنتجات!$G$5:$G$24,MATCH($A11,المنتجات!$A$5:$A$24,0)),0))) | K11: =IF(OR($A11="",$C11=""),"",N(F11)*IF(E11="لكل حبة",SUMIFS(الإنتاج!$G$5:$G$504,الإنتاج!$C$5:$C$504,$A11),SUMIFS(الإنتاج!$E$5:$E$504,الإنتاج!$C$5:$C$504,$A11)))
B12: =IF($A12="","",IFERROR(INDEX(المنتجات!$C$5:$C$24,MATCH($A12,المنتجات!$A$5:$A$24,0)),"كود غير موجود")) | D12: =IF($C12="","",IFERROR(INDEX('المواد الخام'!$B$5:$B$104,MATCH($C12,'المواد الخام'!$A$5:$A$104,0)),"كود غير موجود")) | G12: =IF($C12="","",IFERROR(INDEX('المواد الخام'!$D$5:$D$104,MATCH($C12,'المواد الخام'!$A$5:$A$104,0)),"")) | H12: =IF($C12="","",IFERROR(INDEX('المواد الخام'!$G$5:$G$104,MATCH($C12,'المواد الخام'!$A$5:$A$104,0)),0)) | I12: =IF($C12="","",N(F12)*N(H12)) | J12: =IF(OR($A12="",$C12=""),"",IF(E12="لكل حبة",I12,IFERROR(I12/INDEX(المنتجات!$G$5:$G$24,MATCH($A12,المنتجات!$A$5:$A$24,0)),0))) | K12: =IF(OR($A12="",$C12=""),"",N(F12)*IF(E12="لكل حبة",SUMIFS(الإنتاج!$G$5:$G$504,الإنتاج!$C$5:$C$504,$A12),SUMIFS(الإنتاج!$E$5:$E$504,الإنتاج!$C$5:$C$504,$A12)))
B13: =IF($A13="","",IFERROR(INDEX(المنتجات!$C$5:$C$24,MATCH($A13,المنتجات!$A$5:$A$24,0)),"كود غير موجود")) | D13: =IF($C13="","",IFERROR(INDEX('المواد الخام'!$B$5:$B$104,MATCH($C13,'المواد الخام'!$A$5:$A$104,0)),"كود غير موجود")) | G13: =IF($C13="","",IFERROR(INDEX('المواد الخام'!$D$5:$D$104,MATCH($C13,'المواد الخام'!$A$5:$A$104,0)),"")) | H13: =IF($C13="","",IFERROR(INDEX('المواد الخام'!$G$5:$G$104,MATCH($C13,'المواد الخام'!$A$5:$A$104,0)),0)) | I13: =IF($C13="","",N(F13)*N(H13)) | J13: =IF(OR($A13="",$C13=""),"",IF(E13="لكل حبة",I13,IFERROR(I13/INDEX(المنتجات!$G$5:$G$24,MATCH($A13,المنتجات!$A$5:$A$24,0)),0))) | K13: =IF(OR($A13="",$C13=""),"",N(F13)*IF(E13="لكل حبة",SUMIFS(الإنتاج!$G$5:$G$504,الإنتاج!$C$5:$C$504,$A13),SUMIFS(الإنتاج!$E$5:$E$504,الإنتاج!$C$5:$C$504,$A13)))
B14: =IF($A14="","",IFERROR(INDEX(المنتجات!$C$5:$C$24,MATCH($A14,المنتجات!$A$5:$A$24,0)),"كود غير موجود")) | D14: =IF($C14="","",IFERROR(INDEX('المواد الخام'!$B$5:$B$104,MATCH($C14,'المواد الخام'!$A$5:$A$104,0)),"كود غير موجود")) | G14: =IF($C14="","",IFERROR(INDEX('المواد الخام'!$D$5:$D$104,MATCH($C14,'المواد الخام'!$A$5:$A$104,0)),"")) | H14: =IF($C14="","",IFERROR(INDEX('المواد الخام'!$G$5:$G$104,MATCH($C14,'المواد الخام'!$A$5:$A$104,0)),0)) | I14: =IF($C14="","",N(F14)*N(H14)) | J14: =IF(OR($A14="",$C14=""),"",IF(E14="لكل حبة",I14,IFERROR(I14/INDEX(المنتجات!$G$5:$G$24,MATCH($A14,المنتجات!$A$5:$A$24,0)),0))) | K14: =IF(OR($A14="",$C14=""),"",N(F14)*IF(E14="لكل حبة",SUMIFS(الإنتاج!$G$5:$G$504,الإنتاج!$C$5:$C$504,$A14),SUMIFS(الإنتاج!$E$5:$E$504,الإنتاج!$C$5:$C$504,$A14)))
B15: =IF($A15="","",IFERROR(INDEX(المنتجات!$C$5:$C$24,MATCH($A15,المنتجات!$A$5:$A$24,0)),"كود غير موجود")) | D15: =IF($C15="","",IFERROR(INDEX('المواد الخام'!$B$5:$B$104,MATCH($C15,'المواد الخام'!$A$5:$A$104,0)),"كود غير موجود")) | G15: =IF($C15="","",IFERROR(INDEX('المواد الخام'!$D$5:$D$104,MATCH($C15,'المواد الخام'!$A$5:$A$104,0)),"")) | H15: =IF($C15="","",IFERROR(INDEX('المواد الخام'!$G$5:$G$104,MATCH($C15,'المواد الخام'!$A$5:$A$104,0)),0)) | I15: =IF($C15="","",N(F15)*N(H15)) | J15: =IF(OR($A15="",$C15=""),"",IF(E15="لكل حبة",I15,IFERROR(I15/INDEX(المنتجات!$G$5:$G$24,MATCH($A15,المنتجات!$A$5:$A$24,0)),0))) | K15: =IF(OR($A15="",$C15=""),"",N(F15)*IF(E15="لكل حبة",SUMIFS(الإنتاج!$G$5:$G$504,الإنتاج!$C$5:$C$504,$A15),SUMIFS(الإنتاج!$E$5:$E$504,الإنتاج!$C$5:$C$504,$A15)))
B16: =IF($A16="","",IFERROR(INDEX(المنتجات!$C$5:$C$24,MATCH($A16,المنتجات!$A$5:$A$24,0)),"كود غير موجود")) | D16: =IF($C16="","",IFERROR(INDEX('المواد الخام'!$B$5:$B$104,MATCH($C16,'المواد الخام'!$A$5:$A$104,0)),"كود غير موجود")) | G16: =IF($C16="","",IFERROR(INDEX('المواد الخام'!$D$5:$D$104,MATCH($C16,'المواد الخام'!$A$5:$A$104,0)),"")) | H16: =IF($C16="","",IFERROR(INDEX('المواد الخام'!$G$5:$G$104,MATCH($C16,'المواد الخام'!$A$5:$A$104,0)),0)) | I16: =IF($C16="","",N(F16)*N(H16)) | J16: =IF(OR($A16="",$C16=""),"",IF(E16="لكل حبة",I16,IFERROR(I16/INDEX(المنتجات!$G$5:$G$24,MATCH($A16,المنتجات!$A$5:$A$24,0)),0))) | K16: =IF(OR($A16="",$C16=""),"",N(F16)*IF(E16="لكل حبة",SUMIFS(الإنتاج!$G$5:$G$504,الإنتاج!$C$5:$C$504,$A16),SUMIFS(الإنتاج!$E$5:$E$504,الإنتاج!$C$5:$C$504,$A16)))
B17: =IF($A17="","",IFERROR(INDEX(المنتجات!$C$5:$C$24,MATCH($A17,المنتجات!$A$5:$A$24,0)),"كود غير موجود")) | D17: =IF($C17="","",IFERROR(INDEX('المواد الخام'!$B$5:$B$104,MATCH($C17,'المواد الخام'!$A$5:$A$104,0)),"كود غير موجود")) | G17: =IF($C17="","",IFERROR(INDEX('المواد الخام'!$D$5:$D$104,MATCH($C17,'المواد الخام'!$A$5:$A$104,0)),"")) | H17: =IF($C17="","",IFERROR(INDEX('المواد الخام'!$G$5:$G$104,MATCH($C17,'المواد الخام'!$A$5:$A$104,0)),0)) | I17: =IF($C17="","",N(F17)*N(H17)) | J17: =IF(OR($A17="",$C17=""),"",IF(E17="لكل حبة",I17,IFERROR(I17/INDEX(المنتجات!$G$5:$G$24,MATCH($A17,المنتجات!$A$5:$A$24,0)),0))) | K17: =IF(OR($A17="",$C17=""),"",N(F17)*IF(E17="لكل حبة",SUMIFS(الإنتاج!$G$5:$G$504,الإنتاج!$C$5:$C$504,$A17),SUMIFS(الإنتاج!$E$5:$E$504,الإنتاج!$C$5:$C$504,$A17)))
B18: =IF($A18="","",IFERROR(INDEX(المنتجات!$C$5:$C$24,MATCH($A18,المنتجات!$A$5:$A$24,0)),"كود غير موجود")) | D18: =IF($C18="","",IFERROR(INDEX('المواد الخام'!$B$5:$B$104,MATCH($C18,'المواد الخام'!$A$5:$A$104,0)),"كود غير موجود")) | G18: =IF($C18="","",IFERROR(INDEX('المواد الخام'!$D$5:$D$104,MATCH($C18,'المواد الخام'!$A$5:$A$104,0)),"")) | H18: =IF($C18="","",IFERROR(INDEX('المواد الخام'!$G$5:$G$104,MATCH($C18,'المواد الخام'!$A$5:$A$104,0)),0)) | I18: =IF($C18="","",N(F18)*N(H18)) | J18: =IF(OR($A18="",$C18=""),"",IF(E18="لكل حبة",I18,IFERROR(I18/INDEX(المنتجات!$G$5:$G$24,MATCH($A18,المنتجات!$A$5:$A$24,0)),0))) | K18: =IF(OR($A18="",$C18=""),"",N(F18)*IF(E18="لكل حبة",SUMIFS(الإنتاج!$G$5:$G$504,الإنتاج!$C$5:$C$504,$A18),SUMIFS(الإنتاج!$E$5:$E$504,الإنتاج!$C$5:$C$504,$A18)))
B19: =IF($A19="","",IFERROR(INDEX(المنتجات!$C$5:$C$24,MATCH($A19,المنتجات!$A$5:$A$24,0)),"كود غير موجود")) | D19: =IF($C19="","",IFERROR(INDEX('المواد الخام'!$B$5:$B$104,MATCH($C19,'المواد الخام'!$A$5:$A$104,0)),"كود غير موجود")) | G19: =IF($C19="","",IFERROR(INDEX('المواد الخام'!$D$5:$D$104,MATCH($C19,'المواد الخام'!$A$5:$A$104,0)),"")) | H19: =IF($C19="","",IFERROR(INDEX('المواد الخام'!$G$5:$G$104,MATCH($C19,'المواد الخام'!$A$5:$A$104,0)),0)) | I19: =IF($C19="","",N(F19)*N(H19)) | J19: =IF(OR($A19="",$C19=""),"",IF(E19="لكل حبة",I19,IFERROR(I19/INDEX(المنتجات!$G$5:$G$24,MATCH($A19,المنتجات!$A$5:$A$24,0)),0))) | K19: =IF(OR($A19="",$C19=""),"",N(F19)*IF(E19="لكل حبة",SUMIFS(الإنتاج!$G$5:$G$504,الإنتاج!$C$5:$C$504,$A19),SUMIFS(الإنتاج!$E$5:$E$504,الإنتاج!$C$5:$C$504,$A19)))
B20: =IF($A20="","",IFERROR(INDEX(المنتجات!$C$5:$C$24,MATCH($A20,المنتجات!$A$5:$A$24,0)),"كود غير موجود")) | D20: =IF($C20="","",IFERROR(INDEX('المواد الخام'!$B$5:$B$104,MATCH($C20,'المواد الخام'!$A$5:$A$104,0)),"كود غير موجود")) | G20: =IF($C20="","",IFERROR(INDEX('المواد الخام'!$D$5:$D$104,MATCH($C20,'المواد الخام'!$A$5:$A$104,0)),"")) | H20: =IF($C20="","",IFERROR(INDEX('المواد الخام'!$G$5:$G$104,MATCH($C20,'المواد الخام'!$A$5:$A$104,0)),0)) | I20: =IF($C20="","",N(F20)*N(H20)) | J20: =IF(OR($A20="",$C20=""),"",IF(E20="لكل حبة",I20,IFERROR(I20/INDEX(المنتجات!$G$5:$G$24,MATCH($A20,المنتجات!$A$5:$A$24,0)),0))) | K20: =IF(OR($A20="",$C20=""),"",N(F20)*IF(E20="لكل حبة",SUMIFS(الإنتاج!$G$5:$G$504,الإنتاج!$C$5:$C$504,$A20),SUMIFS(الإنتاج!$E$5:$E$504,الإنتاج!$C$5:$C$504,$A20)))
... B304: =IF($A304="","",IFERROR(INDEX(المنتجات!$C$5:$C$24,MATCH($A304,المنتجات!$A$5:$A$24,0)),"كود غير موجود")) | D304: =IF($C304="","",IFERROR(INDEX('المواد الخام'!$B$5:$B$104,MATCH($C304,'المواد الخام'!$A$5:$A$104,0)),"كود غير موجود")) | G304: =IF($C304="","",IFERROR(INDEX('المواد الخام'!$D$5:$D$104,MATCH($C304,'المواد الخام'!$A$5:$A$104,0)),"")) | H304: =IF($C304="","",IFERROR(INDEX('المواد الخام'!$G$5:$G$104,MATCH($C304,'المواد الخام'!$A$5:$A$104,0)),0)) | I304: =IF($C304="","",N(F304)*N(H304)) | J304: =IF(OR($A304="",$C304=""),"",IF(E304="لكل حبة",I304,IFERROR(I304/INDEX(المنتجات!$G$5:$G$24,MATCH($A304,المنتجات!$A$5:$A$24,0)),0))) | K304: =IF(OR($A304="",$C304=""),"",N(F304)*IF(E304="لكل حبة",SUMIFS(الإنتاج!$G$5:$G$504,الإنتاج!$C$5:$C$504,$A304),SUMIFS(الإنتاج!$E$5:$E$504,الإنتاج!$C$5:$C$504,$A304)))

Sheet المواد الخام
A1: المواد الخام والتغليف
A2: كل مادة تُسجل هنا مرة وحدة بكود ثابت. الوحدة الأساسية: جرام للمواد الصلبة، مل للسوائل، حبة للتغليف. التكلفة تُحسب تلقائياً من مشترياتك في صفحة حركة المخزون (متوسط مرجح)، وإذا ما فيه مشتريات تُحسب من السعر اليدوي.
A4: الكود | B4: اسم المادة | C4: النوع | D4: الوحدة | E4: سعر آخر شراء (ر.س) | F4: الكمية المشتراة (بالوحدة) | G4: تكلفة الوحدة | H4: رصيد افتتاحي | I4: الوارد (مشتريات) | J4: المستهلك في الإنتاج | K4: تالف وتسويات (صافي) | L4: الرصيد الحالي | M4: حد الطلب | N4: الحالة | O4: قيمة المخزون | P4: المورد | Q4: ملاحظات
A5: RM-001 | B5: بودرة عود | C5: مادة خام | D5: جرام | G5: =IF($A5="","",IFERROR(SUMIFS('حركة المخزون'!$G$5:$G$1004,'حركة المخزون'!$C$5:$C$1004,$A5,'حركة المخزون'!$B$5:$B$1004,"وارد شراء")/SUMIFS('حركة المخزون'!$E$5:$E$1004,'حركة المخزون'!$C$5:$C$1004,$A5,'حركة المخزون'!$B$5:$B$1004,"وارد شراء"),IFERROR(E5/F5,0))) -> 0 | I5: =IF($A5="","",SUMIFS('حركة المخزون'!$E$5:$E$1004,'حركة المخزون'!$C$5:$C$1004,$A5,'حركة المخزون'!$B$5:$B$1004,"وارد شراء")) -> 0 | J5: =IF($A5="","",SUMIFS(الوصفات!$K$5:$K$304,الوصفات!$C$5:$C$304,$A5)) -> 0 | K5: =IF($A5="","",SUMIFS('حركة المخزون'!$E$5:$E$1004,'حركة المخزون'!$C$5:$C$1004,$A5,'حركة المخزون'!$B$5:$B$1004,"تسوية زيادة")-SUMIFS('حركة المخزون'!$E$5:$E$1004,'حركة المخزون'!$C$5:$C$1004,$A5,'حركة المخزون'!$B$5:$B$1004,"تالف")-SUMIFS('حركة المخزون'!$E$5:$E$1004,'حركة المخزون'!$C$5:$C$1004,$A5,'حركة المخزون'!$B$5:$B$1004,"عينة / هدية")-SUMIFS('حركة المخزون'!$E$5:$E$1004,'حركة المخزون'!$C$5:$C$1004,$A5,'حركة المخزون'!$B$5:$B$1004,"تسوية نقص")) -> 0 | L5: =IF($A5="","",N(H5)+I5-J5+K5) -> 0 | N5: =IF($A5="","",IF(AND(H5="",I5=0,J5=0),"لم يُسجل رصيد",IF(L5<=0,"نفد",IF(L5<=N(M5),"اطلب الآن","متوفر")))) -> لم يُسجل رصيد | O5: =IF($A5="","",L5*G5) -> 0 | Q5: قائمة مبدئية — عدّل الاسم أو احذف
A6: RM-002 | B6: زيت عطري (خلطة المعمول) | C6: مادة خام | D6: جرام | G6: =IF($A6="","",IFERROR(SUMIFS('حركة المخزون'!$G$5:$G$1004,'حركة المخزون'!$C$5:$C$1004,$A6,'حركة المخزون'!$B$5:$B$1004,"وارد شراء")/SUMIFS('حركة المخزون'!$E$5:$E$1004,'حركة المخزون'!$C$5:$C$1004,$A6,'حركة المخزون'!$B$5:$B$1004,"وارد شراء"),IFERROR(E6/F6,0))) -> 0 | I6: =IF($A6="","",SUMIFS('حركة المخزون'!$E$5:$E$1004,'حركة المخزون'!$C$5:$C$1004,$A6,'حركة المخزون'!$B$5:$B$1004,"وارد شراء")) -> 0 | J6: =IF($A6="","",SUMIFS(الوصفات!$K$5:$K$304,الوصفات!$C$5:$C$304,$A6)) -> 0 | K6: =IF($A6="","",SUMIFS('حركة المخزون'!$E$5:$E$1004,'حركة المخزون'!$C$5:$C$1004,$A6,'حركة المخزون'!$B$5:$B$1004,"تسوية زيادة")-SUMIFS('حركة المخزون'!$E$5:$E$1004,'حركة المخزون'!$C$5:$C$1004,$A6,'حركة المخزون'!$B$5:$B$1004,"تالف")-SUMIFS('حركة المخزون'!$E$5:$E$1004,'حركة المخزون'!$C$5:$C$1004,$A6,'حركة المخزون'!$B$5:$B$1004,"عينة / هدية")-SUMIFS('حركة المخزون'!$E$5:$E$1004,'حركة المخزون'!$C$5:$C$1004,$A6,'حركة المخزون'!$B$5:$B$1004,"تسوية نقص")) -> 0 | L6: =IF($A6="","",N(H6)+I6-J6+K6) -> 0 | N6: =IF($A6="","",IF(AND(H6="",I6=0,J6=0),"لم يُسجل رصيد",IF(L6<=0,"نفد",IF(L6<=N(M6),"اطلب الآن","متوفر")))) -> لم يُسجل رصيد | O6: =IF($A6="","",L6*G6) -> 0 | Q6: قائمة مبدئية — عدّل الاسم أو احذف
A7: RM-003 | B7: مسك | C7: مادة خام | D7: جرام | G7: =IF($A7="","",IFERROR(SUMIFS('حركة المخزون'!$G$5:$G$1004,'حركة المخزون'!$C$5:$C$1004,$A7,'حركة المخزون'!$B$5:$B$1004,"وارد شراء")/SUMIFS('حركة المخزون'!$E$5:$E$1004,'حركة المخزون'!$C$5:$C$1004,$A7,'حركة المخزون'!$B$5:$B$1004,"وارد شراء"),IFERROR(E7/F7,0))) -> 0 | I7: =IF($A7="","",SUMIFS('حركة المخزون'!$E$5:$E$1004,'حركة المخزون'!$C$5:$C$1004,$A7,'حركة المخزون'!$B$5:$B$1004,"وارد شراء")) -> 0 | J7: =IF($A7="","",SUMIFS(الوصفات!$K$5:$K$304,الوصفات!$C$5:$C$304,$A7)) -> 0 | K7: =IF($A7="","",SUMIFS('حركة المخزون'!$E$5:$E$1004,'حركة المخزون'!$C$5:$C$1004,$A7,'حركة المخزون'!$B$5:$B$1004,"تسوية زيادة")-SUMIFS('حركة المخزون'!$E$5:$E$1004,'حركة المخزون'!$C$5:$C$1004,$A7,'حركة المخزون'!$B$5:$B$1004,"تالف")-SUMIFS('حركة المخزون'!$E$5:$E$1004,'حركة المخزون'!$C$5:$C$1004,$A7,'حركة المخزون'!$B$5:$B$1004,"عينة / هدية")-SUMIFS('حركة المخزون'!$E$5:$E$1004,'حركة المخزون'!$C$5:$C$1004,$A7,'حركة المخزون'!$B$5:$B$1004,"تسوية نقص")) -> 0 | L7: =IF($A7="","",N(H7)+I7-J7+K7) -> 0 | N7: =IF($A7="","",IF(AND(H7="",I7=0,J7=0),"لم يُسجل رصيد",IF(L7<=0,"نفد",IF(L7<=N(M7),"اطلب الآن","متوفر")))) -> لم يُسجل رصيد | O7: =IF($A7="","",L7*G7) -> 0 | Q7: قائمة مبدئية — عدّل الاسم أو احذف
A8: RM-004 | B8: عنبر | C8: مادة خام | D8: جرام | G8: =IF($A8="","",IFERROR(SUMIFS('حركة المخزون'!$G$5:$G$1004,'حركة المخزون'!$C$5:$C$1004,$A8,'حركة المخزون'!$B$5:$B$1004,"وارد شراء")/SUMIFS('حركة المخزون'!$E$5:$E$1004,'حركة المخزون'!$C$5:$C$1004,$A8,'حركة المخزون'!$B$5:$B$1004,"وارد شراء"),IFERROR(E8/F8,0))) -> 0 | I8: =IF($A8="","",SUMIFS('حركة المخزون'!$E$5:$E$1004,'حركة المخزون'!$C$5:$C$1004,$A8,'حركة المخزون'!$B$5:$B$1004,"وارد شراء")) -> 0 | J8: =IF($A8="","",SUMIFS(الوصفات!$K$5:$K$304,الوصفات!$C$5:$C$304,$A8)) -> 0 | K8: =IF($A8="","",SUMIFS('حركة المخزون'!$E$5:$E$1004,'حركة المخزون'!$C$5:$C$1004,$A8,'حركة المخزون'!$B$5:$B$1004,"تسوية زيادة")-SUMIFS('حركة المخزون'!$E$5:$E$1004,'حركة المخزون'!$C$5:$C$1004,$A8,'حركة المخزون'!$B$5:$B$1004,"تالف")-SUMIFS('حركة المخزون'!$E$5:$E$1004,'حركة المخزون'!$C$5:$C$1004,$A8,'حركة المخزون'!$B$5:$B$1004,"عينة / هدية")-SUMIFS('حركة المخزون'!$E$5:$E$1004,'حركة المخزون'!$C$5:$C$1004,$A8,'حركة المخزون'!$B$5:$B$1004,"تسوية نقص")) -> 0 | L8: =IF($A8="","",N(H8)+I8-J8+K8) -> 0 | N8: =IF($A8="","",IF(AND(H8="",I8=0,J8=0),"لم يُسجل رصيد",IF(L8<=0,"نفد",IF(L8<=N(M8),"اطلب الآن","متوفر")))) -> لم يُسجل رصيد | O8: =IF($A8="","",L8*G8) -> 0 | Q8: قائمة مبدئية — عدّل الاسم أو احذف
A9: RM-005 | B9: عود خام (قطع) | C9: مادة خام | D9: جرام | G9: =IF($A9="","",IFERROR(SUMIFS('حركة المخزون'!$G$5:$G$1004,'حركة المخزون'!$C$5:$C$1004,$A9,'حركة المخزون'!$B$5:$B$1004,"وارد شراء")/SUMIFS('حركة المخزون'!$E$5:$E$1004,'حركة المخزون'!$C$5:$C$1004,$A9,'حركة المخزون'!$B$5:$B$1004,"وارد شراء"),IFERROR(E9/F9,0))) -> 0 | I9: =IF($A9="","",SUMIFS('حركة المخزون'!$E$5:$E$1004,'حركة المخزون'!$C$5:$C$1004,$A9,'حركة المخزون'!$B$5:$B$1004,"وارد شراء")) -> 0 | J9: =IF($A9="","",SUMIFS(الوصفات!$K$5:$K$304,الوصفات!$C$5:$C$304,$A9)) -> 0 | K9: =IF($A9="","",SUMIFS('حركة المخزون'!$E$5:$E$1004,'حركة المخزون'!$C$5:$C$1004,$A9,'حركة المخزون'!$B$5:$B$1004,"تسوية زيادة")-SUMIFS('حركة المخزون'!$E$5:$E$1004,'حركة المخزون'!$C$5:$C$1004,$A9,'حركة المخزون'!$B$5:$B$1004,"تالف")-SUMIFS('حركة المخزون'!$E$5:$E$1004,'حركة المخزون'!$C$5:$C$1004,$A9,'حركة المخزون'!$B$5:$B$1004,"عينة / هدية")-SUMIFS('حركة المخزون'!$E$5:$E$1004,'حركة المخزون'!$C$5:$C$1004,$A9,'حركة المخزون'!$B$5:$B$1004,"تسوية نقص")) -> 0 | L9: =IF($A9="","",N(H9)+I9-J9+K9) -> 0 | N9: =IF($A9="","",IF(AND(H9="",I9=0,J9=0),"لم يُسجل رصيد",IF(L9<=0,"نفد",IF(L9<=N(M9),"اطلب الآن","متوفر")))) -> لم يُسجل رصيد | O9: =IF($A9="","",L9*G9) -> 0 | Q9: قائمة مبدئية — عدّل الاسم أو احذف
A10: RM-006 | B10: دهن تسقية العود | C10: مادة خام | D10: مل | G10: =IF($A10="","",IFERROR(SUMIFS('حركة المخزون'!$G$5:$G$1004,'حركة المخزون'!$C$5:$C$1004,$A10,'حركة المخزون'!$B$5:$B$1004,"وارد شراء")/SUMIFS('حركة المخزون'!$E$5:$E$1004,'حركة المخزون'!$C$5:$C$1004,$A10,'حركة المخزون'!$B$5:$B$1004,"وارد شراء"),IFERROR(E10/F10,0))) -> 0 | I10: =IF($A10="","",SUMIFS('حركة المخزون'!$E$5:$E$1004,'حركة المخزون'!$C$5:$C$1004,$A10,'حركة المخزون'!$B$5:$B$1004,"وارد شراء")) -> 0 | J10: =IF($A10="","",SUMIFS(الوصفات!$K$5:$K$304,الوصفات!$C$5:$C$304,$A10)) -> 0 | K10: =IF($A10="","",SUMIFS('حركة المخزون'!$E$5:$E$1004,'حركة المخزون'!$C$5:$C$1004,$A10,'حركة المخزون'!$B$5:$B$1004,"تسوية زيادة")-SUMIFS('حركة المخزون'!$E$5:$E$1004,'حركة المخزون'!$C$5:$C$1004,$A10,'حركة المخزون'!$B$5:$B$1004,"تالف")-SUMIFS('حركة المخزون'!$E$5:$E$1004,'حركة المخزون'!$C$5:$C$1004,$A10,'حركة المخزون'!$B$5:$B$1004,"عينة / هدية")-SUMIFS('حركة المخزون'!$E$5:$E$1004,'حركة المخزون'!$C$5:$C$1004,$A10,'حركة المخزون'!$B$5:$B$1004,"تسوية نقص")) -> 0 | L10: =IF($A10="","",N(H10)+I10-J10+K10) -> 0 | N10: =IF($A10="","",IF(AND(H10="",I10=0,J10=0),"لم يُسجل رصيد",IF(L10<=0,"نفد",IF(L10<=N(M10),"اطلب الآن","متوفر")))) -> لم يُسجل رصيد | O10: =IF($A10="","",L10*G10) -> 0 | Q10: قائمة مبدئية — عدّل الاسم أو احذف
A11: RM-007 | B11: دهن عود طبيعي (خام) | C11: مادة خام | D11: جرام | G11: =IF($A11="","",IFERROR(SUMIFS('حركة المخزون'!$G$5:$G$1004,'حركة المخزون'!$C$5:$C$1004,$A11,'حركة المخزون'!$B$5:$B$1004,"وارد شراء")/SUMIFS('حركة المخزون'!$E$5:$E$1004,'حركة المخزون'!$C$5:$C$1004,$A11,'حركة المخزون'!$B$5:$B$1004,"وارد شراء"),IFERROR(E11/F11,0))) -> 0 | I11: =IF($A11="","",SUMIFS('حركة المخزون'!$E$5:$E$1004,'حركة المخزون'!$C$5:$C$1004,$A11,'حركة المخزون'!$B$5:$B$1004,"وارد شراء")) -> 0 | J11: =IF($A11="","",SUMIFS(الوصفات!$K$5:$K$304,الوصفات!$C$5:$C$304,$A11)) -> 0 | K11: =IF($A11="","",SUMIFS('حركة المخزون'!$E$5:$E$1004,'حركة المخزون'!$C$5:$C$1004,$A11,'حركة المخزون'!$B$5:$B$1004,"تسوية زيادة")-SUMIFS('حركة المخزون'!$E$5:$E$1004,'حركة المخزون'!$C$5:$C$1004,$A11,'حركة المخزون'!$B$5:$B$1004,"تالف")-SUMIFS('حركة المخزون'!$E$5:$E$1004,'حركة المخزون'!$C$5:$C$1004,$A11,'حركة المخزون'!$B$5:$B$1004,"عينة / هدية")-SUMIFS('حركة المخزون'!$E$5:$E$1004,'حركة المخزون'!$C$5:$C$1004,$A11,'حركة المخزون'!$B$5:$B$1004,"تسوية نقص")) -> 0 | L11: =IF($A11="","",N(H11)+I11-J11+K11) -> 0 | N11: =IF($A11="","",IF(AND(H11="",I11=0,J11=0),"لم يُسجل رصيد",IF(L11<=0,"نفد",IF(L11<=N(M11),"اطلب الآن","متوفر")))) -> لم يُسجل رصيد | O11: =IF($A11="","",L11*G11) -> 0 | Q11: قائمة مبدئية — عدّل الاسم أو احذف
A12: RM-008 | B12: زعفران | C12: مادة خام | D12: جرام | G12: =IF($A12="","",IFERROR(SUMIFS('حركة المخزون'!$G$5:$G$1004,'حركة المخزون'!$C$5:$C$1004,$A12,'حركة المخزون'!$B$5:$B$1004,"وارد شراء")/SUMIFS('حركة المخزون'!$E$5:$E$1004,'حركة المخزون'!$C$5:$C$1004,$A12,'حركة المخزون'!$B$5:$B$1004,"وارد شراء"),IFERROR(E12/F12,0))) -> 0 | I12: =IF($A12="","",SUMIFS('حركة المخزون'!$E$5:$E$1004,'حركة المخزون'!$C$5:$C$1004,$A12,'حركة المخزون'!$B$5:$B$1004,"وارد شراء")) -> 0 | J12: =IF($A12="","",SUMIFS(الوصفات!$K$5:$K$304,الوصفات!$C$5:$C$304,$A12)) -> 0 | K12: =IF($A12="","",SUMIFS('حركة المخزون'!$E$5:$E$1004,'حركة المخزون'!$C$5:$C$1004,$A12,'حركة المخزون'!$B$5:$B$1004,"تسوية زيادة")-SUMIFS('حركة المخزون'!$E$5:$E$1004,'حركة المخزون'!$C$5:$C$1004,$A12,'حركة المخزون'!$B$5:$B$1004,"تالف")-SUMIFS('حركة المخزون'!$E$5:$E$1004,'حركة المخزون'!$C$5:$C$1004,$A12,'حركة المخزون'!$B$5:$B$1004,"عينة / هدية")-SUMIFS('حركة المخزون'!$E$5:$E$1004,'حركة المخزون'!$C$5:$C$1004,$A12,'حركة المخزون'!$B$5:$B$1004,"تسوية نقص")) -> 0 | L12: =IF($A12="","",N(H12)+I12-J12+K12) -> 0 | N12: =IF($A12="","",IF(AND(H12="",I12=0,J12=0),"لم يُسجل رصيد",IF(L12<=0,"نفد",IF(L12<=N(M12),"اطلب الآن","متوفر")))) -> لم يُسجل رصيد | O12: =IF($A12="","",L12*G12) -> 0 | Q12: قائمة مبدئية — عدّل الاسم أو احذف
A13: RM-009 | B13: قاعدة المرش (ماء / كحول) | C13: مادة خام | D13: مل | G13: =IF($A13="","",IFERROR(SUMIFS('حركة المخزون'!$G$5:$G$1004,'حركة المخزون'!$C$5:$C$1004,$A13,'حركة المخزون'!$B$5:$B$1004,"وارد شراء")/SUMIFS('حركة المخزون'!$E$5:$E$1004,'حركة المخزون'!$C$5:$C$1004,$A13,'حركة المخزون'!$B$5:$B$1004,"وارد شراء"),IFERROR(E13/F13,0))) -> 0 | I13: =IF($A13="","",SUMIFS('حركة المخزون'!$E$5:$E$1004,'حركة المخزون'!$C$5:$C$1004,$A13,'حركة المخزون'!$B$5:$B$1004,"وارد شراء")) -> 0 | J13: =IF($A13="","",SUMIFS(الوصفات!$K$5:$K$304,الوصفات!$C$5:$C$304,$A13)) -> 0 | K13: =IF($A13="","",SUMIFS('حركة المخزون'!$E$5:$E$1004,'حركة المخزون'!$C$5:$C$1004,$A13,'حركة المخزون'!$B$5:$B$1004,"تسوية زيادة")-SUMIFS('حركة المخزون'!$E$5:$E$1004,'حركة المخزون'!$C$5:$C$1004,$A13,'حركة المخزون'!$B$5:$B$1004,"تالف")-SUMIFS('حركة المخزون'!$E$5:$E$1004,'حركة المخزون'!$C$5:$C$1004,$A13,'حركة المخزون'!$B$5:$B$1004,"عينة / هدية")-SUMIFS('حركة المخزون'!$E$5:$E$1004,'حركة المخزون'!$C$5:$C$1004,$A13,'حركة المخزون'!$B$5:$B$1004,"تسوية نقص")) -> 0 | L13: =IF($A13="","",N(H13)+I13-J13+K13) -> 0 | N13: =IF($A13="","",IF(AND(H13="",I13=0,J13=0),"لم يُسجل رصيد",IF(L13<=0,"نفد",IF(L13<=N(M13),"اطلب الآن","متوفر")))) -> لم يُسجل رصيد | O13: =IF($A13="","",L13*G13) -> 0 | Q13: قائمة مبدئية — عدّل الاسم أو احذف
A14: RM-010 | B14: زيت عطري للمرشات | C14: مادة خام | D14: مل | G14: =IF($A14="","",IFERROR(SUMIFS('حركة المخزون'!$G$5:$G$1004,'حركة المخزون'!$C$5:$C$1004,$A14,'حركة المخزون'!$B$5:$B$1004,"وارد شراء")/SUMIFS('حركة المخزون'!$E$5:$E$1004,'حركة المخزون'!$C$5:$C$1004,$A14,'حركة المخزون'!$B$5:$B$1004,"وارد شراء"),IFERROR(E14/F14,0))) -> 0 | I14: =IF($A14="","",SUMIFS('حركة المخزون'!$E$5:$E$1004,'حركة المخزون'!$C$5:$C$1004,$A14,'حركة المخزون'!$B$5:$B$1004,"وارد شراء")) -> 0 | J14: =IF($A14="","",SUMIFS(الوصفات!$K$5:$K$304,الوصفات!$C$5:$C$304,$A14)) -> 0 | K14: =IF($A14="","",SUMIFS('حركة المخزون'!$E$5:$E$1004,'حركة المخزون'!$C$5:$C$1004,$A14,'حركة المخزون'!$B$5:$B$1004,"تسوية زيادة")-SUMIFS('حركة المخزون'!$E$5:$E$1004,'حركة المخزون'!$C$5:$C$1004,$A14,'حركة المخزون'!$B$5:$B$1004,"تالف")-SUMIFS('حركة المخزون'!$E$5:$E$1004,'حركة المخزون'!$C$5:$C$1004,$A14,'حركة المخزون'!$B$5:$B$1004,"عينة / هدية")-SUMIFS('حركة المخزون'!$E$5:$E$1004,'حركة المخزون'!$C$5:$C$1004,$A14,'حركة المخزون'!$B$5:$B$1004,"تسوية نقص")) -> 0 | L14: =IF($A14="","",N(H14)+I14-J14+K14) -> 0 | N14: =IF($A14="","",IF(AND(H14="",I14=0,J14=0),"لم يُسجل رصيد",IF(L14<=0,"نفد",IF(L14<=N(M14),"اطلب الآن","متوفر")))) -> لم يُسجل رصيد | O14: =IF($A14="","",L14*G14) -> 0 | Q14: قائمة مبدئية — عدّل الاسم أو احذف
